Workbook

Sheet 版本
A1: 版本 | B1: 更新日期 | C1: 作者 | D1: 更新內容 | E1: 備註
A2: V0.1 | B2: 45615 | C2: Wayne | D2: 初版文件完成 | E2: 完成1~50關物件，但改變位移的相關物件先不納入。並增加字彙表、定義消除行為。
A3: V0.11 | B3: 45616 | C3: Wayne | D3: 清單調整 | E3: 發現一開始的清單內，關於RoyalMatch的部分有錯誤，已調整為正確內容。
A4: V0.2 | B4: 45636 | C4: Wayne | D4: 更新內容 | E4: 開始製作餐具櫃和藥水櫃文件，並新增層級、數量和消除冷卻相關內容。
A5: V0.21 | B5: 45643 | C5: Wayne | D5: 更新內容 | E5: 移除消除冷卻相關內容，新增高度說明。
A6: V0.22 | B6: 45644 | C6: Wayne | D6: 更新內容 | E6: 大幅調整物件清單順序，以規則機制面對齊Royal Match為原則。
A7: V0.23 | B7: 45650 | C7: Wayne | D7: 清單改版 | E7: 將障礙物以其特殊功能分類，避免每個障礙物文件塞入過多細節造成資訊高度重複。
A8: V0.24 | B8: 45652 | C8: Wayne | D8: 內容改版 | E8: 重製編號1~11的文件內容，並且新增大量字彙表內容。
A9: V0.25 | B9: 45659 | C9: Wayne | D9: 內容改版 | E9: 新增編號12~22的物件文件內容。
A10: V0.26 | B10: 45660 | C10: Wayne | D10: 內容改版 | E10: 修改容器障礙物說明、修改單次消除定義。
A11: V0.27 | B11: 45665 | C11: Wayne | D11: 新增內容 | E11: 23~40物件先行調研。
A12: V0.28 | B12: 45666 | C12: Wayne | D12: 紙風車補充
A13: V1.0 | B13: 45812 | C13: Wayne | D13: 開圖準備
A14: V1.1 | B14: 45917 | C14: Wayne | D14: 新增內容 | E14: 18~26+30號物件

Sheet 清單
A1: 6 | B1: 紙箱 | C1: 一般型 | F1: 固定 | G1: 單次消除 | H1: 鄰邊消除 | I1: 道具消除 | J1: Box | K1: 1 | M1: 製造機 | O1: 其他
A2: 10 | B2: 木桶 | C2: 一般型 | F2: 移動 | G2: 單次消除 | H2: 鄰邊消除 | I2: 道具消除 | J2: Royal Egg | K2: 31 | M2: 特殊
A3: 12 | B3: 交通錐 | C3: 一般型 | F3: 移動 | G3: 單次消除 | H3: 鄰邊消除 | I3: 道具消除 | J3: Vase | K3: 51 | M3: Royal Match 1~100關影片
A4: 13 | B4: 路障 | C4: 一般型 | F4: 移動 | G4: 單次消除 | H4: 鄰邊消除 | I4: 道具消除 | J4: Vase | K4: 51 | M4: Royal Match - Levels 1 - 100 - YouTube
A5: 14 | B5: 罐頭 | C5: 一般型 | F5: 固定 | G5: 單次消除 | H5: 道具消除 | J5: Owl | K5: 61 | P5: 遮蔽是假議題
A6: 15 | B6: 充氣游泳池 | C6: 一般型 | D6: 複數地塊 | F6: 固定 | G6: 單次消除 | H6: 鄰邊消除 | I6: 道具消除 | J6: Bush | K6: 71 | P6: 視覺上的遮蔽與否取決與美術圖，預設規則是可移動的不會完全遮蔽，固定的大部分都遮蔽
A7: 18 | B7: 保險箱 | C7: 一般型 | F7: 固定 | G7: 單次消除 | H7: 道具消除 | J7: Safe | K7: 91 | L7: 旅館常見保險箱 | M7: 5層 | P7: 回收型物件則不算，在消除判定上無視該物件進行判定即可
A8: 20 | B8: 彩色紙箱 | C8: 一般型 | D8: 對應顏色 | F8: 固定 | G8: 單次消除 | H8: 鄰邊消除 | I8: 道具消除 | J8: Color Box | K8: 121 | L8: 彩色紙箱 | M8: 1~4層
A9: 22 | B9: 瓶中信 | C9: 一般型 | F9: 固定 | G9: 單次消除 | H9: 道具消除 | J9: Porcelain Piggy | K9: 161 | L9: 瓶中信 | P9: 障礙物的設計取向並非線性的提高消除層數
A10: 24 | B10: 泡麵 | C10: 一般型 | F10: 移動 | G10: 單次消除 | H10: 鄰邊消除 | I10: 道具消除 | J10: https://royalmatch.fandom.com/wiki/Oyster | K10: 201 | L10: 泡麵 | M10: 越消越整齊 | N10: 編消+道具消3次消除
A11: 26 | B11: 水球 | C11: 一般型 | D11: 對應顏色 | E11: 特殊屬性 | F11: 移動 | G11: 單次消除 | H11: 鄰邊消除 | I11: 道具消除 | J11: https://royalmatch.fandom.com/wiki/Rock | K11: 261 | L11: 水球(越打越大) | M11: 爆掉噴水漥 | N11: 邊消+道具消2次打成落葉 | P11: 如鑽頭、青蛙、鳥巢等
A12: 30 | B12: 玻璃罐頭 | C12: 一般型 | E12: 特殊屬性 | F12: 固定 | G12: 單次消除 | H12: 鄰邊消除 | I12: 道具消除 | K12: 301 | L12: 第一階段道具消，第二階段邊消+道具消
A13: 31 | B13: 磚頭花圃 | C13: 一般型 | D13: 複數地塊 | E13: 特殊屬性 | F13: 固定 | G13: 多次消除 | H13: 鄰邊消除 | I13: 道具消除 | L13: 磚頭花圃
A14: 16 | B14: 繩索 | C14: 上層型 | D14: 特殊屬性 | F14: 固定 | G14: 單次消除 | H14: 道具消除 | I14: 原地消除 | J14: Chain | K14: 951 | P14: 消除上的判定是只要同一格上有不同高度的物件
A15: 17 | B15: 泥巴 | C15: 上層型 | F15: 固定 | G15: 單次消除 | H15: 鄰邊消除 | I15: 道具消除 | J15: Honey | K15: 81 | P15: 則要先消除上層才能消除中層，消除中層才能消除下層
A16: 7 | B16: 水漥 | C16: 下層型 | F16: 固定 | G16: 單次消除 | H16: 原地消除 | I16: 道具消除 | J16: Grass | K16: 4 | M16: 上層型
A17: 8 | B17: 礦泉水櫃 | C17: 容器 | D17: 複數地塊 | F17: 固定 | G17: 混合消除 | H17: 鄰邊消除 | I17: 道具消除 | J17: Cupboard | K17: 11 | M17: 下層型
A18: 11 | B18: 飲料櫃 | C18: 容器 | D18: 複數地塊 | E18: 對應顏色 | F18: 固定 | G18: 單次消除 | H18: 鄰邊消除 | I18: 道具消除 | J18: Potion Bottle | K18: 41
A19: 27 | B19: 炸藥盒 | C19: 容器 | D19: 特殊屬性 | F19: 固定 | G19: 混合消除 | H19: 鄰邊消除 | I19: 道具消除 | J19: https://royalmatch.fandom.com/wiki/Dynamite_Box | K19: 351
A20: 28 | B20: 杯架 | C20: 容器 | D20: 複數地塊 | E20: 特殊屬性 | F20: 固定 | G20: 混合消除 | H20: 鄰邊消除 | I20: 道具消除 | K20: 401
A21: 29 | B21: 鳥巢 | C21: 容器 | D21: 複數地塊 | E21: 特殊屬性 | F21: 固定 | G21: 混合消除 | H21: 鄰邊消除 | I21: 道具消除 | K21: 451 | L21: 扭蛋機
A22: 39 | B22: 小袋 | C22: 容器 | D22: 特殊屬性 | F22: 移動 | G22: 多次消除 | H22: 鄰邊消除 | I22: 道具消除
A23: 41 | B23: 保齡球盒 | C23: 容器 | D23: 複數地塊 | F23: 固定 | G23: 多次消除 | H23: 鄰邊消除 | I23: 道具消除
A24: 21 | B24: 禁入膠帶 | C24: 特殊 | D24: 複數地塊 | E24: 特殊屬性 | F24: 固定 | G24: 多次消除 | H24: 鄰邊消除 | I24: 道具消除 | J24: Ice/potion tube | K24: 141/9401 | L24: 禁止進入膠帶(粗)
A25: 23 | B25: 鐵捲門 | C25: 特殊 | D25: 複數地塊 | E25: 特殊屬性 | F25: 固定 | G25: 其他 | J25: Curtain | K25: 181 | L25: 鐵捲門(休息中) | P25: 而是在原本的玩法中加上其他機制，或加入不同的階段變化
A26: 32 | B26: 鑽頭 | C26: 特殊 | D26: 複數地塊 | E26: 對應顏色 | F26: 固定 | G26: 其他 | L26: 收集到需求的顏色元素後，鑽頭啟動並破換路徑上所有障礙物。
A27: 33 | B27: 燈泡 | C27: 特殊 | D27: 複數地塊 | E27: 特殊屬性
A28: 35 | B28: 金屬管 | C28: 特殊 | D28: 複數地塊 | F28: 固定 | G28: 單次消除 | H28: 道具消除
A29: 37 | B29: 領結 | C29: 特殊 | D29: 特殊屬性 | F29: 移動 | G29: 多次消除 | H29: 鄰邊消除 | I29: 道具消除 | L29: 打開才能消除，關閉時無敵。
A30: 1 | B30: 基本元素 | C30: 基本元素 | F30: 移動 | G30: 單次消除 | H30: 同色拼湊 | I30: 道具消除 | J30: Match_Items | K30: 1 | M30: 基本元素 | O30: 拼湊消除 | P30: 同色拼湊 | Q30: 固定
A31: 19 | B31: 拖鞋 | C31: 接收型 | D31: 特殊屬性 | F31: 移動 | G31: 接收消除 | J31: Bird | K31: 101 | L31: 扭蛋
A32: 34 | B32: 青蛙 | C32: 接收型 | D32: 特殊屬性 | F32: 移動+自動 | G32: 接收消除 | L32: 如果有一回合沒往下掉，那他就會往上跳一格。
A33: 40 | B33: 燈籠 | C33: 連續型 | F33: 固定 | G33: 多次消除 | H33: 鄰邊消除 | I33: 道具消除
A34: 2 | B34: 火箭 | C34: 道具 | F34: 移動 | G34: 單次消除 | H34: 使用 | I34: 道具消除 | J34: Rocket | K34: 2 | M34: 道具 | N34: 複數地塊 | O34: 單次消除 | P34: 使用 | Q34: 移動
A35: 3 | B35: 炸彈 | C35: 道具 | F35: 移動 | G35: 單次消除 | H35: 使用 | I35: 道具消除 | J35: TNT | K35: 3 | M35: 一般型 | N35: 對應顏色 | O35: 多次消除 | P35: 鄰邊消除 | Q35: 移動+自動
A36: 4 | B36: 螺旋槳 | C36: 道具 | F36: 移動 | G36: 單次消除 | H36: 使用 | I36: 道具消除 | J36: Propeller | K36: 4 | M36: 容器 | N36: 特殊屬性 | O36: 混合消除 | P36: 道具消除
A37: 5 | B37: 紙風車 | C37: 道具 | F37: 移動 | G37: 單次消除 | H37: 使用 | I37: 道具消除 | J37: Light Ball | K37: 5 | M37: 接收型 | O37: 接收消除 | P37: 原地消除
A38: 9 | B38: 郵戳印章 | C38: 製造機 | F38: 固定 | G38: 單次消除 | H38: 鄰邊消除 | I38: 道具消除 | J38: Mailbox | K38: 21 | M38: 連續型
A39: 25 | B39: 兌幣機 | C39: 製造機 | F39: 固定 | G39: 單次消除 | H39: 鄰邊消除 | I39: 道具消除 | J39: https://royalmatch.fandom.com/wiki/Magic_Hat | K39: 231 | L39: 兌幣機 | M39: 打會噴零錢 | N39: 打3次生出n個新色的元素。 | P39: 讓玩家可以建立明確的階段消除目標，並且產生新的、難預測的盤面
A40: 36 | B40: 罐子 | C40: 製造機 | D40: 特殊屬性 | F40: 固定 | G40: 多次消除 | H40: 鄰邊消除 | I40: 道具消除 | L40: 達到目標需求後罐子會消失。
...

Sheet Glossary
A1: 專案詞彙表
A3: 編號 | B3: 中文 | C3: 英文(非必要) | D3: 意涵
A4: 1 | B4: 物件 | C4: Object | D4: 所有在地塊上可編輯的東西，包含：元素、道具、金幣、障礙物、地形...等。
A5: 2 | B5: 滑動 | C5: Swipe | D5: 玩家將地塊上的可移動物件拖曳到鄰近地塊上，並因此觸發兩個地塊上的可移動物件位置互換。
A6: 3 | B6: 消除 | C6: Remove | D6: 使物件降低層數或消失於盤面上的動作，若消除範圍包含道具，也會使道具被使用。
A7: 4 | B7: 盤外道具 | C7: Booster | D7: 透過獎勵、消費等方式獲得的遊戲道具，可保存並於遊戲關卡內隨時使用，且不會因使用而消耗一步。通常在關卡內顯示於畫面下方，便於讓玩家使用。
A8: 5 | B8: 盤內道具 | C8: Power-ups | D8: 透過遊戲內的元素合成及連續通關獎勵系統，出現在關卡盤面上的道具。具有消除效果，範圍及作用各有不同。
A9: 6 | B9: 道具合成 | C9: Combine | D9: 使用滑動，將一個盤內道具拖曳到另一個道具上。兩個道具在合成後會立即使用，並具有更強大的效果。
A10: 7 | B10: 基本元素 | C10: Element | D10: 是組成盤面最基礎的物件，共有六種顏色。可用同色元素拼湊成特殊排列後消除自身，並產生道具。可位移、可滑動、可消除。
A11: 8 | B11: 固定 | C11: Stable | D11: 當物件屬性為固定時，代表物件在盤面的位置不會變動，且不會被滑動、交換及掉落。盤面運動屬性為固定的物件，都無法透過生成器生成。
A12: 9 | B12: 移動 | C12: Move | D12: 物件在盤面上，可被玩家滑動，或因為地形特殊效果和下方地塊沒有物件而位移。此類物件皆可透過生成器生成。
A13: 10 | B13: 使用 | C13: Use | D13: 使用的觸發有3種：1.被玩家點擊後在原地使用。2.被玩家滑動後在新地塊位置使用。3.其他道具被使用時，受該道具的消除效果後在原地使用。
A14: 11 | B14: 延伸 | C14: Extend | D14: 會在符合條件的地塊生出相同的物件。
A15: 12 | B15: 層級 | C15: Phase | D15: 障礙物需要消除的階段數，障礙物的層級至少為1。單一障礙物的不同層級可以容許單次消除和多次消除並存，層級也可能具有消除數量。
... A39: 36 | B39: 其他 | C39: Other | D39: 代表有其他的消除方式，會特別註明。

Sheet 消除定義
A1: 消除定義
B3: 排列與生成物
C5: 1.消除行為
D6: 消除行為分為以下三種
E7: A.在盤面上將相同的元素湊成特定排列組合時，可觸發消除行為
E9: B.當使用道具後，對無特定排列組合的元素觸發消除行為
E11: C.在A和B的形況下，對特定物件產生邊消(EX: 木箱)、或直接消除(EX: 繩索)。
C15: 2.消除點
D16: 每個消除行為發生時，都存在至少一個消除點。
D17: 消除點代表的是當消除行為產生時，觸發消除動作的關鍵點。
D19: 在消除行為A發生的時候，最後觸發特定排序的物件，就是消除點。
D21: 在特定排列消除時生成的道具，會以消除點為基準位置生成。
D23: 範例
D34: 在消除行為B發生的時候，因為道具而受到消除的無特定排序組合的物件，消除點都為物件本體。
D35: 即便因為道具使用，而消除了複數物件。每個物件的消除都為單一獨立的消除行為。
D38: 在消除行為C發生的時候，因為物件受到邊消或直接消除的位置為消除點。
D39: 若是單一物件在多個位置同時發生消除(發生於尺寸大於1*1的物件)，
D40: 則從被消除的物件的每個位置隨機則依作為消除點。(確認是否會出現問題)
C44: 3.消除次數
D45: A.單次消除
E46: 設定為單次消除的障礙物，在一次消除行為下，只能被消除一次。
E47: 由該次消除行為引發的道具連鎖反應或複數消除地塊，都屬於該次消除。
D49: B.多次消除
E50: 障礙物受到幾次消除，就會造成幾次消除，沒有其他條件。
D52: C.混合消除
E53: 單一障礙物中，如果存在單次消除的層級和多次消除的層級，定義為混合消除，避免混淆。

Sheet 1.元素+元素生成器
A1: 基本元素 | C1: 靜態圖檔名： | D1: SimpleChip_Maruko | H1: 返回清單
A3: 1 | B3: 元素關鍵字
C4: 類型 | D4: 屬性1 | E4: 屬性2 | F4: 盤面運動 | G4: 消除類型 | H4: 消除方式1 | I4: 消除方式2 | J4: RM對應 | K4: RM初現關卡
C5: {=XLOOKUP($A$1,'清單'!$B$4:$B$26,'清單'!C4:C26,0,1,1)} -> 一般型 | D5: {=XLOOKUP($A$1,'清單'!$B$4:$B$26,'清單'!D4:D26,0,1,1)} -> 對應顏色 | E5: {=XLOOKUP($A$1,'清單'!$B$4:$B$26,'清單'!E4:E26,0,1,1)} | F5: {=XLOOKUP($A$1,'清單'!$B$4:$B$26,'清單'!F4:F26,0,1,1)} -> 固定 | G5: {=XLOOKUP($A$1,'清單'!$B$4:$B$26,'清單'!G4:G26,0,1,1)} -> 單次消除 | H5: {=XLOOKUP($A$1,'清單'!$B$4:$B$26,'清單'!H4:H26,0,1,1)} -> 鄰邊消除 | I5: {=XLOOKUP($A$1,'清單'!$B$4:$B$26,'清單'!I4:I26,0,1,1)} -> 道具消除 | J5: {=XLOOKUP($A$1,'清單'!$B$4:$B$26,'清單'!J4:J26,0,1,1)} -> Color Box | K5: {=XLOOKUP($A$1,'清單'!$B$4:$B$26,'清單'!K4:K26,0,1,1)} -> 121
N7: 同場加映
A8: 2 | B8: 元素特性規則 | M8: 2.5 | N8: 「元素生成器」特性規則
C9: =C4 -> 類型 | D9: 描述 | N9: 元素生成器為透明、無碰撞的無形物件。
C10: =C5 -> 一般型 | D10: {=XLOOKUP($C$5,Glossary!$B:$B,Glossary!$D:$D,1,1,1)} -> 最基礎的障礙物，具備1~N層，主要透過鄰邊消除和道具消除的手段來消除。 | N10: 可被所有物件覆蓋，可在所有地形設置。
C12: 屬性1 | D12: 描述 | N12: 在生成器存在的地塊為空時，開始生成元素。
C13: =if(ISBLANK($D$5),"無",CONCATENATE($D$5)) -> 對應顏色 | D13: {=if(ISBLANK($D$5),"無",XLOOKUP($D$5,Glossary!B:B,Glossary!D:D,1,1,1))} -> 需要對應顏色的元素消除才能做出有效消除。
N14: 可生成的元素顏色自動和盤面元素顏色設定參數同步。
C15: 屬性2 | D15: 描述 | N15: 在預設狀態下，將隨機生成盤面設定的元素顏色，且各顏色的生成機率均等。
C16: =if(ISBLANK($E$5),"無",CONCATENATE($E$5)) -> 無 | D16: {=if(ISBLANK($E$5),"無",XLOOKUP($E$5,Glossary!B:B,Glossary!D:D,1,1,1))} -> 無
N17: 元素會由該地塊行進方向的反方向邊緣出現。
C18: 盤面運動 | D18: 描述
C19: =if(ISBLANK($F$5),,CONCATENATE($F$5)) -> 固定 | D19: {=if(ISBLANK($F$5),,XLOOKUP($F$5,Glossary!B:B,Glossary!D:D,1,1,1))} -> 當物件屬性為固定時，代表物件在盤面的位置不會變動，且不會被滑動、交換及掉落。盤面運動屬性為固定的物件，都無法透過生成器生成。
C21: 消除類型 | D21: 描述
C22: =if(ISBLANK($G$5),"無",CONCATENATE($G$5)) -> 單次消除 | D22: {=if(ISBLANK($G$5),"無",XLOOKUP($G$5,Glossary!B:B,Glossary!D:D,1,1,1))} -> 設定為單次消除的層級，在一次消除行為下，只能被消除一次。該次消除行為包含的複數地塊消除，都算是該單次消除行為。
C24: 消除方式1 | D24: 描述
C25: =if(ISBLANK($H$5),"無",CONCATENATE($H$5)) -> 鄰邊消除 | D25: {=if(ISBLANK($H$5),,XLOOKUP($H$5,Glossary!B:B,Glossary!D:D,1,1,1))} -> 在與物件相鄰的地塊觸發消除行為時，會對物件產生消除效果。
C27: 消除方式2 | D27: 描述
C28: =if(ISBLANK($I$5),"無",CONCATENATE($I$5)) -> 道具消除 | D28: {=if(ISBLANK($I$5),,XLOOKUP($I$5,Glossary!B:B,Glossary!D:D,1,1,1))} -> 由道具發出的消除行為，會對物件產生消除效果。
C30: 用相同的元素湊齊特定排列後，可以自我消除，並根據排列而於消除點生成不同的道具。
C31: 詳細規則見下方元素排列及生成物說明
M32: 3.5 | N32: 元素生成器參數
N33: 可設定生成的不同顏色元素的機率，預設為X種色機率均等。X=盤面元素顏色數量。
N34: 元素生成器也須設定可掉落其他的物件，生成器可編輯的參數大致如下，但目前不用。
A35: 3 | B35: 元素特性參數 | O35: A | P35: 不同的物件機率 | Q35: (預設所有非元素物件的掉落機率為0)
C36: A.顏色 | D36: 紅 | E36: 0 | O36: B | P36: 物件的層數 | Q36: (如果該物件有層數)
D37: 綠 | E37: 1 | O37: C | P37: 單一生成器生成該物件的最大數量 | R37: (預設為無限制)
D38: 藍 | E38: 2 | O38: D | P38: 全局生成器生成該物件的最大數量(預設為無限制)
D39: 黃 | E39: 3
D40: 紫 | E40: 4
D41: 棕 | E41: 5
C42: 編輯器可設定盤面的元素顏色數量，數量範圍是3~5種。
C43: 編輯器也可針對盤面上的元素編輯顏色，預設為隨機。
C44: 預設由上至下增加。
C45: 如：3色，則預設為紅、綠、藍；四色，則預設為紅、綠、藍、黃....依此類推。
C47: 編輯器可設定生成器的各顏色元素生成機率，預設為各種顏色均等。
C49: B.元素的消除排列及生成物
...

Sheet 2.火箭
A1: 火箭 | C1: 靜態圖檔名： | D1: HorizontalGrayBomb_Maruko_01、VerticalGrayBomb_Maruko_01 | H1: 返回清單
A3: 1 | B3: 關鍵字
C4: 類型 | D4: 屬性1 | E4: 屬性2 | F4: 盤面運動 | G4: 消除類型 | H4: 消除方式1 | I4: 消除方式2 | J4: RM對應 | K4: RM初現關卡
C5: {=XLOOKUP($A$1,'清單'!$B$4:$B$26,'清單'!C4:C26,0,1,1)} -> 一般型 | D5: {=XLOOKUP($A$1,'清單'!$B$4:$B$26,'清單'!D4:D26,0,1,1)} -> 複數地塊 | E5: {=XLOOKUP($A$1,'清單'!$B$4:$B$26,'清單'!E4:E26,0,1,1)} | F5: {=XLOOKUP($A$1,'清單'!$B$4:$B$26,'清單'!F4:F26,0,1,1)} -> 固定 | G5: {=XLOOKUP($A$1,'清單'!$B$4:$B$26,'清單'!G4:G26,0,1,1)} -> 單次消除 | H5: {=XLOOKUP($A$1,'清單'!$B$4:$B$26,'清單'!H4:H26,0,1,1)} -> 鄰邊消除 | I5: {=XLOOKUP($A$1,'清單'!$B$4:$B$26,'清單'!I4:I26,0,1,1)} -> 道具消除 | J5: {=XLOOKUP($A$1,'清單'!$B$4:$B$26,'清單'!J4:J26,0,1,1)} -> Bush | K5: {=XLOOKUP($A$1,'清單'!$B$4:$B$26,'清單'!K4:K26,0,1,1)} -> 71
A8: 2 | B8: 特性規則
C9: =C4 -> 類型 | D9: 描述
C10: =C5 -> 一般型 | D10: {=XLOOKUP($C$5,Glossary!$B:$B,Glossary!$D:$D,1,1,1)} -> 最基礎的障礙物，具備1~N層，主要透過鄰邊消除和道具消除的手段來消除。
C12: 屬性1 | D12: 描述
C13: =if(ISBLANK($D$5),"無",CONCATENATE($D$5)) -> 複數地塊 | D13: {=if(ISBLANK($D$5),"無",XLOOKUP($D$5,Glossary!B:B,Glossary!D:D,1,1,1))} -> 物件最小存在單位超過一個地塊。
C15: 屬性2 | D15: 描述
C16: =if(ISBLANK($E$5),"無",CONCATENATE($E$5)) -> 無 | D16: {=if(ISBLANK($E$5),"無",XLOOKUP($E$5,Glossary!B:B,Glossary!D:D,1,1,1))} -> 無
C18: 盤面運動 | D18: 描述
C19: =if(ISBLANK($F$5),,CONCATENATE($F$5)) -> 固定 | D19: {=if(ISBLANK($F$5),,XLOOKUP($F$5,Glossary!B:B,Glossary!D:D,1,1,1))} -> 當物件屬性為固定時，代表物件在盤面的位置不會變動，且不會被滑動、交換及掉落。盤面運動屬性為固定的物件，都無法透過生成器生成。
C21: 消除類型 | D21: 描述
C22: =if(ISBLANK($G$5),"無",CONCATENATE($G$5)) -> 單次消除 | D22: {=if(ISBLANK($G$5),"無",XLOOKUP($G$5,Glossary!B:B,Glossary!D:D,1,1,1))} -> 設定為單次消除的層級，在一次消除行為下，只能被消除一次。該次消除行為包含的複數地塊消除，都算是該單次消除行為。
C24: 消除方式1 | D24: 描述
C25: =if(ISBLANK($H$5),"無",CONCATENATE($H$5)) -> 鄰邊消除 | D25: {=if(ISBLANK($H$5),,XLOOKUP($H$5,Glossary!B:B,Glossary!D:D,1,1,1))} -> 在與物件相鄰的地塊觸發消除行為時，會對物件產生消除效果。
C27: 消除方式2 | D27: 描述
C28: =if(ISBLANK($I$5),"無",CONCATENATE($I$5)) -> 道具消除 | D28: {=if(ISBLANK($I$5),,XLOOKUP($I$5,Glossary!B:B,Glossary!D:D,1,1,1))} -> 由道具發出的消除行為，會對物件產生消除效果。
C31: 特殊的是在盤面上透過元素生成的火箭，和拼湊方向不同。
C32: 橫向拼湊而成的4消，生成的是垂直火箭。
C33: 直向拼湊而成的4消，生成的是水平火箭。
C35: 消除效果是由道具使用點中心往外延伸，具有些微的時間差。
C37: 當玩家將火箭往其他元素滑動後，火箭會與其他道具結合後立刻使用，並產生更強的效果。
C38: A | D38: 火箭、紙飛機合成
D39: 會先觸發火箭的上下左右四格消除後，飛到新位置使用火箭。
C41: B | D41: 火箭、火箭合成
D42: 在結合的地塊同時產生垂直火箭和水平火箭的效果，造成十字型的範圍消除。
C44: C | D44: 火箭、炸彈合成
D45: 以結合的地塊為中心的九宮格，同時產生垂直火箭和水平火箭的效果，造成寬度為3的十字型範圍消除。
C47: D | D47: 火箭、紙風車合成
D48: 在結合的地塊先觸發紙風車選取元素的效果，隨後將選取的元素全部轉變為火箭後使用。
A51: 3 | B51: 特性參數
C52: 編輯器可設定生成器的火箭生成機率和生成火箭的方向，預設機率為0。
C54: 編輯器可設定單一生成器的火箭最大生成數量，預設為無限制。
C56: 編輯器可設定全局火箭最大生成數量，預設為無限制。

Sheet 3.炸彈
A1: 炸彈 | C1: 靜態圖檔名： | D1: GrayBomb_Maruko | H1: 返回清單
A3: 1 | B3: 關鍵字
C4: 類型 | D4: 屬性1 | E4: 屬性2 | F4: 盤面運動 | G4: 消除類型 | H4: 消除方式1 | I4: 消除方式2 | J4: RM對應 | K4: RM初現關卡
C5: {=XLOOKUP($A$1,'清單'!$B$4:$B$26,'清單'!C4:C26,0,1,1)} -> 容器 | D5: {=XLOOKUP($A$1,'清單'!$B$4:$B$26,'清單'!D4:D26,0,1,1)} -> 特殊屬性 | E5: {=XLOOKUP($A$1,'清單'!$B$4:$B$26,'清單'!E4:E26,0,1,1)} | F5: {=XLOOKUP($A$1,'清單'!$B$4:$B$26,'清單'!F4:F26,0,1,1)} -> 固定 | G5: {=XLOOKUP($A$1,'清單'!$B$4:$B$26,'清單'!G4:G26,0,1,1)} -> 混合消除 | H5: {=XLOOKUP($A$1,'清單'!$B$4:$B$26,'清單'!H4:H26,0,1,1)} -> 鄰邊消除 | I5: {=XLOOKUP($A$1,'清單'!$B$4:$B$26,'清單'!I4:I26,0,1,1)} -> 道具消除 | J5: {=XLOOKUP($A$1,'清單'!$B$4:$B$26,'清單'!J4:J26,0,1,1)} -> https://royalmatch.fandom.com/wiki/Dynamite_Box | K5: {=XLOOKUP($A$1,'清單'!$B$4:$B$26,'清單'!K4:K26,0,1,1)} -> 351
A8: 2 | B8: 特性規則
C9: =C4 -> 類型 | D9: 描述
C10: =C5 -> 容器 | D10: {=XLOOKUP($C$5,Glossary!$B:$B,Glossary!$D:$D,1,1,1)} -> 容器障礙物一般來說分成兩個階段，階段1為單次消除打開層級，可能有數層。階段2具有單次消除或多次消除的內容物。
C12: 屬性1 | D12: 描述
C13: =if(ISBLANK($D$5),"無",CONCATENATE($D$5)) -> 特殊屬性 | D13: {=if(ISBLANK($D$5),"無",XLOOKUP($D$5,Glossary!B:B,Glossary!D:D,1,1,1))} -> 雖然障礙物大致上符合某種類型的劃分，但有局部獨特的效果屬性，在清單中以此做分類，並會在該障礙物文件中詳細闡述。
C15: 屬性2 | D15: 描述
C16: =if(ISBLANK($E$5),"無",CONCATENATE($E$5)) -> 無 | D16: {=if(ISBLANK($E$5),"無",XLOOKUP($E$5,Glossary!B:B,Glossary!D:D,1,1,1))} -> 無
C18: 盤面運動 | D18: 描述
C19: =if(ISBLANK($F$5),,CONCATENATE($F$5)) -> 固定 | D19: {=if(ISBLANK($F$5),,XLOOKUP($F$5,Glossary!B:B,Glossary!D:D,1,1,1))} -> 當物件屬性為固定時，代表物件在盤面的位置不會變動，且不會被滑動、交換及掉落。盤面運動屬性為固定的物件，都無法透過生成器生成。
C21: 消除類型 | D21: 描述
C22: =if(ISBLANK($G$5),"無",CONCATENATE($G$5)) -> 混合消除 | D22: {=if(ISBLANK($G$5),"無",XLOOKUP($G$5,Glossary!B:B,Glossary!D:D,1,1,1))} -> 單一障礙物的不同層級，存在單次消除和多次消除的設定，定義為混合消除。避免設計者混淆。
C24: 消除方式1 | D24: 描述
C25: =if(ISBLANK($H$5),"無",CONCATENATE($H$5)) -> 鄰邊消除 | D25: {=if(ISBLANK($H$5),,XLOOKUP($H$5,Glossary!B:B,Glossary!D:D,1,1,1))} -> 在與物件相鄰的地塊觸發消除行為時，會對物件產生消除效果。
C27: 消除方式2 | D27: 描述
C28: =if(ISBLANK($I$5),"無",CONCATENATE($I$5)) -> 道具消除 | D28: {=if(ISBLANK($I$5),,XLOOKUP($I$5,Glossary!B:B,Glossary!D:D,1,1,1))} -> 由道具發出的消除行為，會對物件產生消除效果。
C31: 消除效果是由道具使用點中心往外延伸，具有些微的時間差。 | K31: 生成炸彈的元素排列如下：
C32: 爆炸範圍示意圖如下
C45: 當玩家將火箭往其他道具滑動後，火箭會與其他道具合成後立刻使用，並產生更強的效果。
C46: A | D46: 炸彈、紙飛機合成
D47: 會先觸發火箭的上下左右四格消除後，飛到新位置使用炸彈。
C49: B | D49: 炸彈、火箭合成 | E49: 見右圖
D50: 以結合的地塊為中心的九宮格，同時產生垂直火箭和水平火箭的效果，造成寬度為3的十字型範圍消除。
C52: C | D52: 炸彈、炸彈合成 | E52: 見右圖
D53: 在結合的地塊產生更大的消除範圍。
C55: D | D55: 炸彈、紙風車合成
D56: 在合成的物件位置先觸發紙風車選取元素的效果，隨後將選取的元素全部轉變為炸彈後使用。
A59: 3 | B59: 特性參數
C60: 編輯器可設定生成器的炸彈生成機率，預設機率為0。
C62: 編輯器可設定單一生成器的炸彈最大生成數量，預設為無限制。
C64: 編輯器可設定全局炸彈最大生成數量，預設為無限制。

Sheet 4.螺旋槳
A1: 紙飛機 | C1: 靜態圖檔名： | D1: AirPlaneBomb_Y | H1: 返回清單
A3: 1 | B3: 關鍵字
C4: 類型 | D4: 屬性1 | E4: 屬性2 | F4: 盤面運動 | G4: 消除類型 | H4: 消除方式1 | I4: 消除方式2 | J4: RM對應 | K4: RM初現關卡
C5: {=XLOOKUP($A$1,'清單'!$B$4:$B$26,'清單'!C4:C26,0,1,1)} -> 一般型 | D5: {=XLOOKUP($A$1,'清單'!$B$4:$B$26,'清單'!D4:D26,0,1,1)} -> 對應顏色 | E5: {=XLOOKUP($A$1,'清單'!$B$4:$B$26,'清單'!E4:E26,0,1,1)} | F5: {=XLOOKUP($A$1,'清單'!$B$4:$B$26,'清單'!F4:F26,0,1,1)} -> 固定 | G5: {=XLOOKUP($A$1,'清單'!$B$4:$B$26,'清單'!G4:G26,0,1,1)} -> 單次消除 | H5: {=XLOOKUP($A$1,'清單'!$B$4:$B$26,'清單'!H4:H26,0,1,1)} -> 鄰邊消除 | I5: {=XLOOKUP($A$1,'清單'!$B$4:$B$26,'清單'!I4:I26,0,1,1)} -> 道具消除 | J5: {=XLOOKUP($A$1,'清單'!$B$4:$B$26,'清單'!J4:J26,0,1,1)} -> Color Box | K5: {=XLOOKUP($A$1,'清單'!$B$4:$B$26,'清單'!K4:K26,0,1,1)} -> 121
A8: 2 | B8: 特性規則
C9: =C4 -> 類型 | D9: 描述
C10: =C5 -> 一般型 | D10: {=XLOOKUP($C$5,Glossary!$B:$B,Glossary!$D:$D,1,1,1)} -> 最基礎的障礙物，具備1~N層，主要透過鄰邊消除和道具消除的手段來消除。
C12: 屬性1 | D12: 描述
C13: =if(ISBLANK($D$5),"無",CONCATENATE($D$5)) -> 對應顏色 | D13: {=if(ISBLANK($D$5),"無",XLOOKUP($D$5,Glossary!B:B,Glossary!D:D,1,1,1))} -> 需要對應顏色的元素消除才能做出有效消除。
C15: 屬性2 | D15: 描述
C16: =if(ISBLANK($E$5),"無",CONCATENATE($E$5)) -> 無 | D16: {=if(ISBLANK($E$5),"無",XLOOKUP($E$5,Glossary!B:B,Glossary!D:D,1,1,1))} -> 無
C18: 盤面運動 | D18: 描述
C19: =if(ISBLANK($F$5),,CONCATENATE($F$5)) -> 固定 | D19: {=if(ISBLANK($F$5),,XLOOKUP($F$5,Glossary!B:B,Glossary!D:D,1,1,1))} -> 當物件屬性為固定時，代表物件在盤面的位置不會變動，且不會被滑動、交換及掉落。盤面運動屬性為固定的物件，都無法透過生成器生成。
C21: 消除類型 | D21: 描述
C22: =if(ISBLANK($G$5),"無",CONCATENATE($G$5)) -> 單次消除 | D22: {=if(ISBLANK($G$5),"無",XLOOKUP($G$5,Glossary!B:B,Glossary!D:D,1,1,1))} -> 設定為單次消除的層級，在一次消除行為下，只能被消除一次。該次消除行為包含的複數地塊消除，都算是該單次消除行為。
C24: 消除方式1 | D24: 描述
C25: =if(ISBLANK($H$5),"無",CONCATENATE($H$5)) -> 鄰邊消除 | D25: {=if(ISBLANK($H$5),,XLOOKUP($H$5,Glossary!B:B,Glossary!D:D,1,1,1))} -> 在與物件相鄰的地塊觸發消除行為時，會對物件產生消除效果。
C27: 消除方式2 | D27: 描述
C28: =if(ISBLANK($I$5),"無",CONCATENATE($I$5)) -> 道具消除 | D28: {=if(ISBLANK($I$5),,XLOOKUP($I$5,Glossary!B:B,Glossary!D:D,1,1,1))} -> 由道具發出的消除行為，會對物件產生消除效果。
C31: 當紙飛機使用時，會在道具使用點消除上下左右四個鄰近物件後起飛一台紙飛機。(見右圖) | J31: 紙飛機消除效果
C32: 起飛的紙飛機會根據盤面物件的優先級而選定目標，並在撥放飛行動作後，擊中目標並消除。
C33: 根據盤面十字中心線，
C34: 中心線以上觸發(包含中心線)，則向下起飛。
C35: 中心線以下觸發，則向上起飛。
C36: 中心線以左觸發(包含中心線)，則向右起飛。
C37: 中心線以右觸發，則向左起飛。
C39: 當玩家將紙飛機往其他道具滑動後，紙飛機會與其他道具結合並立刻使用，並產生更強的效果。
C40: A | D40: 紙飛機、紙飛機合成
D41: 會先觸發合成點上下左右四格消除後，起飛三台紙飛機。(見右圖)
J42: 紙飛機+紙飛機消除效果
C43: B | D43: 紙飛機、火箭合成
D44: 會先觸發合成點上下左右四格消除後，飛到新位置使用火箭。
C46: C | D46: 紙飛機、炸彈合成
D47: 會先觸發合成點上下左右四格消除後，飛到新位置使用炸彈。
C49: D | D49: 紙飛機、紙風車合成
D50: 在合成的物件位置先觸發紙風車選取元素的效果，隨後將選取的元素全部轉變為紙飛機後使用。
A53: 3 | B53: 紙飛機優先級
C54: 紙飛機起飛時，會根據盤面上物件本身的權重和額外加權計算後，選定加權最高的目標並撞擊。
C56: (目前)物件權重表，0=不會被紙飛機撞擊
C57: 1 | D57: 元素 | E57: 1
...

Sheet 5.紙風車
A1: 紙風車 | C1: 靜態圖檔名： | D1: Cake_Maruko | H1: 返回清單
A3: 1 | B3: 關鍵字
C4: 類型 | D4: 屬性1 | E4: 屬性2 | F4: 盤面運動 | G4: 消除類型 | H4: 消除方式1 | I4: 消除方式2 | J4: RM對應 | K4: RM初現關卡
C5: {=XLOOKUP($A$1,'清單'!$B$4:$B$26,'清單'!C4:C26,0,1,1)} -> 一般型 | D5: {=XLOOKUP($A$1,'清單'!$B$4:$B$26,'清單'!D4:D26,0,1,1)} -> 對應顏色 | E5: {=XLOOKUP($A$1,'清單'!$B$4:$B$26,'清單'!E4:E26,0,1,1)} | F5: {=XLOOKUP($A$1,'清單'!$B$4:$B$26,'清單'!F4:F26,0,1,1)} -> 固定 | G5: {=XLOOKUP($A$1,'清單'!$B$4:$B$26,'清單'!G4:G26,0,1,1)} -> 單次消除 | H5: {=XLOOKUP($A$1,'清單'!$B$4:$B$26,'清單'!H4:H26,0,1,1)} -> 鄰邊消除 | I5: {=XLOOKUP($A$1,'清單'!$B$4:$B$26,'清單'!I4:I26,0,1,1)} -> 道具消除 | J5: {=XLOOKUP($A$1,'清單'!$B$4:$B$26,'清單'!J4:J26,0,1,1)} -> Color Box | K5: {=XLOOKUP($A$1,'清單'!$B$4:$B$26,'清單'!K4:K26,0,1,1)} -> 121
A8: 2 | B8: 特性規則
C9: =C4 -> 類型 | D9: 描述
C10: =C5 -> 一般型 | D10: {=XLOOKUP($C$5,Glossary!$B:$B,Glossary!$D:$D,1,1,1)} -> 最基礎的障礙物，具備1~N層，主要透過鄰邊消除和道具消除的手段來消除。
C12: 屬性1 | D12: 描述
C13: =if(ISBLANK($D$5),"無",CONCATENATE($D$5)) -> 對應顏色 | D13: {=if(ISBLANK($D$5),"無",XLOOKUP($D$5,Glossary!B:B,Glossary!D:D,1,1,1))} -> 需要對應顏色的元素消除才能做出有效消除。
C15: 屬性2 | D15: 描述
C16: =if(ISBLANK($E$5),"無",CONCATENATE($E$5)) -> 無 | D16: {=if(ISBLANK($E$5),"無",XLOOKUP($E$5,Glossary!B:B,Glossary!D:D,1,1,1))} -> 無
C18: 盤面運動 | D18: 描述
C19: =if(ISBLANK($F$5),,CONCATENATE($F$5)) -> 固定 | D19: {=if(ISBLANK($F$5),,XLOOKUP($F$5,Glossary!B:B,Glossary!D:D,1,1,1))} -> 當物件屬性為固定時，代表物件在盤面的位置不會變動，且不會被滑動、交換及掉落。盤面運動屬性為固定的物件，都無法透過生成器生成。
C21: 消除類型 | D21: 描述
C22: =if(ISBLANK($G$5),"無",CONCATENATE($G$5)) -> 單次消除 | D22: {=if(ISBLANK($G$5),"無",XLOOKUP($G$5,Glossary!B:B,Glossary!D:D,1,1,1))} -> 設定為單次消除的層級，在一次消除行為下，只能被消除一次。該次消除行為包含的複數地塊消除，都算是該單次消除行為。
C24: 消除方式1 | D24: 描述
C25: =if(ISBLANK($H$5),"無",CONCATENATE($H$5)) -> 鄰邊消除 | D25: {=if(ISBLANK($H$5),,XLOOKUP($H$5,Glossary!B:B,Glossary!D:D,1,1,1))} -> 在與物件相鄰的地塊觸發消除行為時，會對物件產生消除效果。
C27: 消除方式2 | D27: 描述
C28: =if(ISBLANK($I$5),"無",CONCATENATE($I$5)) -> 道具消除 | D28: {=if(ISBLANK($I$5),,XLOOKUP($I$5,Glossary!B:B,Glossary!D:D,1,1,1))} -> 由道具發出的消除行為，會對物件產生消除效果。
C31: 當紙風車使用時，會根據已下情況而產生不同的效果： | H31: 紙風車生成的元素排列方式：
C32: A | D32: 直接使用
D33: 會選取當前盤面上，數量最多的顏色元素並消除。
C35: B | D35: 被其他道具消除後觸發使用
D36: 同A
C38: C | D38: 和非元素物件交換後使用
D39: 同A
C41: D | D41: 和目標元素交換
D42: 會將盤面上的目標元素全部消除。
C44: E | D44: 和目標道具合成
D45: 會將盤面上最多的元素轉變為目標道具後直接使用。
C47: F | D47: 和紙風車合成
D48: 會將盤面上所有物件消除1層。
A51: 3 | B51: 特性參數
C52: 編輯器可設定生成器的紙風車生成機率，預設機率為0。
C54: 編輯器可設定單一生成器的紙風車最大生成數量，預設為無限制。
C56: 編輯器可設定全局紙風車最大生成數量，預設為無限制。
A59: 4 | B59: 補充說明
C60: 當同時觸發兩個紙風車時
C61: 盤面元素會在在第一個紙風車結束後補滿，
C62: 並讓第二個紙風車可以在啟動後正常消除盤面元素。
...

Sheet 6.紙箱
A1: 紙箱 | C1: 靜態圖檔名： | D1: Sandwich_Box | H1: 返回清單
A3: 1 | B3: 關鍵字
C4: 類型 | D4: 屬性1 | E4: 屬性2 | F4: 盤面運動 | G4: 消除類型 | H4: 消除方式1 | I4: 消除方式2 | J4: RM對應 | K4: RM初現關卡
C5: {=XLOOKUP($A$1,'清單'!$B$4:$B$26,'清單'!C4:C26,0,1,1)} -> 一般型 | D5: {=XLOOKUP($A$1,'清單'!$B$4:$B$26,'清單'!D4:D26,0,1,1)} -> 對應顏色 | E5: {=XLOOKUP($A$1,'清單'!$B$4:$B$26,'清單'!E4:E26,0,1,1)} | F5: {=XLOOKUP($A$1,'清單'!$B$4:$B$26,'清單'!F4:F26,0,1,1)} -> 固定 | G5: {=XLOOKUP($A$1,'清單'!$B$4:$B$26,'清單'!G4:G26,0,1,1)} -> 單次消除 | H5: {=XLOOKUP($A$1,'清單'!$B$4:$B$26,'清單'!H4:H26,0,1,1)} -> 鄰邊消除 | I5: {=XLOOKUP($A$1,'清單'!$B$4:$B$26,'清單'!I4:I26,0,1,1)} -> 道具消除 | J5: {=XLOOKUP($A$1,'清單'!$B$4:$B$26,'清單'!J4:J26,0,1,1)} -> Color Box | K5: {=XLOOKUP($A$1,'清單'!$B$4:$B$26,'清單'!K4:K26,0,1,1)} -> 121
A8: 2 | B8: 特性規則
C9: =C4 -> 類型 | D9: 描述
C10: =C5 -> 一般型 | D10: {=XLOOKUP($C$5,Glossary!$B:$B,Glossary!$D:$D,1,1,1)} -> 最基礎的障礙物，具備1~N層，主要透過鄰邊消除和道具消除的手段來消除。
C12: 屬性1 | D12: 描述
C13: =if(ISBLANK($D$5),"無",CONCATENATE($D$5)) -> 對應顏色 | D13: {=if(ISBLANK($D$5),"無",XLOOKUP($D$5,Glossary!B:B,Glossary!D:D,1,1,1))} -> 需要對應顏色的元素消除才能做出有效消除。
C15: 屬性2 | D15: 描述
C16: =if(ISBLANK($E$5),"無",CONCATENATE($E$5)) -> 無 | D16: {=if(ISBLANK($E$5),"無",XLOOKUP($E$5,Glossary!B:B,Glossary!D:D,1,1,1))} -> 無
C18: 盤面運動 | D18: 描述
C19: =if(ISBLANK($F$5),,CONCATENATE($F$5)) -> 固定 | D19: {=if(ISBLANK($F$5),,XLOOKUP($F$5,Glossary!B:B,Glossary!D:D,1,1,1))} -> 當物件屬性為固定時，代表物件在盤面的位置不會變動，且不會被滑動、交換及掉落。盤面運動屬性為固定的物件，都無法透過生成器生成。
C21: 消除類型 | D21: 描述
C22: =if(ISBLANK($G$5),"無",CONCATENATE($G$5)) -> 單次消除 | D22: {=if(ISBLANK($G$5),"無",XLOOKUP($G$5,Glossary!B:B,Glossary!D:D,1,1,1))} -> 設定為單次消除的層級，在一次消除行為下，只能被消除一次。該次消除行為包含的複數地塊消除，都算是該單次消除行為。
C24: 消除方式1 | D24: 描述
C25: =if(ISBLANK($H$5),"無",CONCATENATE($H$5)) -> 鄰邊消除 | D25: {=if(ISBLANK($H$5),,XLOOKUP($H$5,Glossary!B:B,Glossary!D:D,1,1,1))} -> 在與物件相鄰的地塊觸發消除行為時，會對物件產生消除效果。
C27: 消除方式2 | D27: 描述
C28: =if(ISBLANK($I$5),"無",CONCATENATE($I$5)) -> 道具消除 | D28: {=if(ISBLANK($I$5),,XLOOKUP($I$5,Glossary!B:B,Glossary!D:D,1,1,1))} -> 由道具發出的消除行為，會對物件產生消除效果。
A31: 3 | B31: 特性參數
C32: 編輯器可設定盤面的木箱層數，層數範圍是1~4。
C34: 木箱每層的外型都會有變化。
C36: 編輯器可設定木箱為盤面的通關目標及所需數量
C38: 第一層紙箱上什麼都沒有
C39: 第二層紙箱上貼縱向封箱膠帶
C40: 第三層紙箱上加貼橫向封箱膠帶，膠帶變為十字形
C41: 第四層紙箱上加貼國際紅白邊框寄件單
A44: 4 | B44: 備註
C45: 木箱現在和一般元素同高度，彼此不能覆蓋，請留意。

Sheet 7.水漥
A1: 水漥 | C1: 靜態圖檔名： | D1: Grass | H1: 返回清單
A3: 1 | B3: 關鍵字
C4: 類型 | D4: 屬性1 | E4: 屬性2 | F4: 盤面運動 | G4: 消除類型 | H4: 消除方式1 | I4: 消除方式2 | J4: RM對應 | K4: RM初現關卡
C5: {=XLOOKUP($A$1,'清單'!$B$4:$B$26,'清單'!C4:C26,0,1,1)} -> 下層型 | D5: {=XLOOKUP($A$1,'清單'!$B$4:$B$26,'清單'!D4:D26,0,1,1)} | E5: {=XLOOKUP($A$1,'清單'!$B$4:$B$26,'清單'!E4:E26,0,1,1)} | F5: {=XLOOKUP($A$1,'清單'!$B$4:$B$26,'清單'!F4:F26,0,1,1)} -> 固定 | G5: {=XLOOKUP($A$1,'清單'!$B$4:$B$26,'清單'!G4:G26,0,1,1)} -> 單次消除 | H5: {=XLOOKUP($A$1,'清單'!$B$4:$B$26,'清單'!H4:H26,0,1,1)} -> 原地消除 | I5: {=XLOOKUP($A$1,'清單'!$B$4:$B$26,'清單'!I4:I26,0,1,1)} -> 道具消除 | J5: {=XLOOKUP($A$1,'清單'!$B$4:$B$26,'清單'!J4:J26,0,1,1)} -> Grass | K5: {=XLOOKUP($A$1,'清單'!$B$4:$B$26,'清單'!K4:K26,0,1,1)} -> 4
A8: 2 | B8: 特性規則
C9: =C4 -> 類型 | D9: 描述
C10: =C5 -> 下層型 | D10: {=XLOOKUP($C$5,Glossary!$B:$B,Glossary!$D:$D,1,1,1)} -> 下層型障礙物可以被其他障礙物覆蓋(不可被其他下層型障礙物覆蓋)，在下層型障礙物上還有其他障礙物未消除時，無法影響下層型障礙物。
C12: 屬性1 | D12: 描述
C13: =if(ISBLANK($D$5),"無",CONCATENATE($D$5)) -> 無 | D13: {=if(ISBLANK($D$5),"無",XLOOKUP($D$5,Glossary!B:B,Glossary!D:D,1,1,1))} -> 無
C15: 屬性2 | D15: 描述
C16: =if(ISBLANK($E$5),"無",CONCATENATE($E$5)) -> 無 | D16: {=if(ISBLANK($E$5),"無",XLOOKUP($E$5,Glossary!B:B,Glossary!D:D,1,1,1))} -> 無
C18: 盤面運動 | D18: 描述
C19: =if(ISBLANK($F$5),,CONCATENATE($F$5)) -> 固定 | D19: {=if(ISBLANK($F$5),,XLOOKUP($F$5,Glossary!B:B,Glossary!D:D,1,1,1))} -> 當物件屬性為固定時，代表物件在盤面的位置不會變動，且不會被滑動、交換及掉落。盤面運動屬性為固定的物件，都無法透過生成器生成。
C21: 消除類型 | D21: 描述
C22: =if(ISBLANK($G$5),"無",CONCATENATE($G$5)) -> 單次消除 | D22: {=if(ISBLANK($G$5),"無",XLOOKUP($G$5,Glossary!B:B,Glossary!D:D,1,1,1))} -> 設定為單次消除的層級，在一次消除行為下，只能被消除一次。該次消除行為包含的複數地塊消除，都算是該單次消除行為。
C24: 消除方式1 | D24: 描述
C25: =if(ISBLANK($H$5),"無",CONCATENATE($H$5)) -> 原地消除 | D25: {=if(ISBLANK($H$5),,XLOOKUP($H$5,Glossary!B:B,Glossary!D:D,1,1,1))} -> 在同一個地塊上，由基本元素拼湊後觸發的消除，會對物件產生消除效果。
C27: 消除方式2 | D27: 描述
C28: =if(ISBLANK($I$5),"無",CONCATENATE($I$5)) -> 道具消除 | D28: {=if(ISBLANK($I$5),,XLOOKUP($I$5,Glossary!B:B,Glossary!D:D,1,1,1))} -> 由道具發出的消除行為，會對物件產生消除效果。
A31: 3 | B31: 特性參數
C32: 編輯器可設定盤面的草皮層數，層數範圍是1~2。
C34: 草皮最高有2層，1、2層外觀、顏色略有不同，方便玩家辨識比較層數。
C36: 編輯器可設定草皮為盤面的通關目標及所需數量
C38: 第一層看起來顏色較淺，且積水部分分散，看起來積水少而且淺。
C39: 第二層顏色深一點點，且積水看起來比較多，積水區域完整。
C40: 水漥在與其他水漥在上下左右相鄰的地塊上連接時，邊界會融合，看起來像一整塊水漥。

Sheet 8.礦泉水櫃
A1: 礦泉水櫃 | C1: 靜態圖檔名： | D1: 小丸子專案內無類似靜態圖 | H1: 返回清單
A3: 1 | B3: 關鍵字
C4: 類型 | D4: 屬性1 | E4: 屬性2 | F4: 盤面運動 | G4: 消除類型 | H4: 消除方式1 | I4: 消除方式2 | J4: RM對應 | K4: RM初現關卡
C5: {=XLOOKUP($A$1,'清單'!$B$4:$B$26,'清單'!C4:C26,0,1,1)} -> 容器 | D5: {=XLOOKUP($A$1,'清單'!$B$4:$B$26,'清單'!D4:D26,0,1,1)} -> 複數地塊 | E5: {=XLOOKUP($A$1,'清單'!$B$4:$B$26,'清單'!E4:E26,0,1,1)} | F5: {=XLOOKUP($A$1,'清單'!$B$4:$B$26,'清單'!F4:F26,0,1,1)} -> 固定 | G5: {=XLOOKUP($A$1,'清單'!$B$4:$B$26,'清單'!G4:G26,0,1,1)} -> 混合消除 | H5: {=XLOOKUP($A$1,'清單'!$B$4:$B$26,'清單'!H4:H26,0,1,1)} -> 鄰邊消除 | I5: {=XLOOKUP($A$1,'清單'!$B$4:$B$26,'清單'!I4:I26,0,1,1)} -> 道具消除 | J5: {=XLOOKUP($A$1,'清單'!$B$4:$B$26,'清單'!J4:J26,0,1,1)} -> Cupboard | K5: {=XLOOKUP($A$1,'清單'!$B$4:$B$26,'清單'!K4:K26,0,1,1)} -> 11
A8: 2 | B8: 特性規則
C9: =C4 -> 類型 | D9: 描述
C10: =C5 -> 容器 | D10: {=XLOOKUP($C$5,Glossary!$B:$B,Glossary!$D:$D,1,1,1)} -> 容器障礙物一般來說分成兩個階段，階段1為單次消除打開層級，可能有數層。階段2具有單次消除或多次消除的內容物。
C12: 屬性1 | D12: 描述
C13: =if(ISBLANK($D$5),"無",CONCATENATE($D$5)) -> 複數地塊 | D13: {=if(ISBLANK($D$5),"無",XLOOKUP($D$5,Glossary!B:B,Glossary!D:D,1,1,1))} -> 物件最小存在單位超過一個地塊。
C15: 屬性2 | D15: 描述
C16: =if(ISBLANK($E$5),"無",CONCATENATE($E$5)) -> 無 | D16: {=if(ISBLANK($E$5),"無",XLOOKUP($E$5,Glossary!B:B,Glossary!D:D,1,1,1))} -> 無
C18: 盤面運動 | D18: 描述
C19: =if(ISBLANK($F$5),,CONCATENATE($F$5)) -> 固定 | D19: {=if(ISBLANK($F$5),,XLOOKUP($F$5,Glossary!B:B,Glossary!D:D,1,1,1))} -> 當物件屬性為固定時，代表物件在盤面的位置不會變動，且不會被滑動、交換及掉落。盤面運動屬性為固定的物件，都無法透過生成器生成。
C21: 消除類型 | D21: 描述
C22: =if(ISBLANK($G$5),"無",CONCATENATE($G$5)) -> 混合消除 | D22: {=if(ISBLANK($G$5),"無",XLOOKUP($G$5,Glossary!B:B,Glossary!D:D,1,1,1))} -> 單一障礙物的不同層級，存在單次消除和多次消除的設定，定義為混合消除。避免設計者混淆。
C24: 消除方式1 | D24: 描述
C25: =if(ISBLANK($H$5),"無",CONCATENATE($H$5)) -> 鄰邊消除 | D25: {=if(ISBLANK($H$5),,XLOOKUP($H$5,Glossary!B:B,Glossary!D:D,1,1,1))} -> 在與物件相鄰的地塊觸發消除行為時，會對物件產生消除效果。
C27: 消除方式2 | D27: 描述
C28: =if(ISBLANK($I$5),"無",CONCATENATE($I$5)) -> 道具消除 | D28: {=if(ISBLANK($I$5),,XLOOKUP($I$5,Glossary!B:B,Glossary!D:D,1,1,1))} -> 由道具發出的消除行為，會對物件產生消除效果。
C31: 餐具櫃分為兩個層級，第一層是櫃子關閉狀態，第二層是櫃子打開狀態：
D33: 第一層-櫃子關閉
E34: 此時餐具櫃的層級屬於單次消除，在一次消除行為下，餐具櫃只能被消除一次，不會影響第二層的數量計算。
E35: 由該次消除行為引起的連鎖反應或複數消除地塊，都算是該單次消除行為。
D37: 第二層-櫃子打開
E38: 此時餐具櫃的層級屬於多次消除，餐具櫃受到幾次消除，就會消除幾個盤子，沒有其他條件。
C40: 餐具櫃內固定有10個盤子，不可調整。
A43: 3 | B43: 特性參數
C44: 編輯器可設定礦泉水櫃為盤面的通關目標及所需數量
C45: 固定層數
C48: 第一層，櫃門消失，櫃子成開放式狀態，陳設的10瓶礦泉水可被被消除。
C49: 消除時，礦泉水會彈出後飛往通關資訊區。
C51: 第二層，礦泉水櫃有透明櫃門，被消除時櫃門會彈飛。
C53: 櫃內的飲料都是同一種透明的礦泉水，共10瓶，陳列方式可參考右側櫥櫃內的盤子擺放方式。

Sheet 9.郵戳印章
A1: 郵戳印章 | C1: 靜態圖檔名： | D1: Potted Plants | H1: 返回清單
A3: 1 | B3: 關鍵字
C4: 類型 | D4: 屬性1 | E4: 屬性2 | F4: 盤面運動 | G4: 消除類型 | H4: 消除方式1 | I4: 消除方式2 | J4: RM對應 | K4: RM初現關卡
C5: {=XLOOKUP($A$1,'清單'!$B$4:$B$26,'清單'!C4:C26,0,1,1)} -> 容器 | D5: {=XLOOKUP($A$1,'清單'!$B$4:$B$26,'清單'!D4:D26,0,1,1)} -> 複數地塊 | E5: {=XLOOKUP($A$1,'清單'!$B$4:$B$26,'清單'!E4:E26,0,1,1)} -> 對應顏色 | F5: {=XLOOKUP($A$1,'清單'!$B$4:$B$26,'清單'!F4:F26,0,1,1)} -> 固定 | G5: {=XLOOKUP($A$1,'清單'!$B$4:$B$26,'清單'!G4:G26,0,1,1)} -> 單次消除 | H5: {=XLOOKUP($A$1,'清單'!$B$4:$B$26,'清單'!H4:H26,0,1,1)} -> 鄰邊消除 | I5: {=XLOOKUP($A$1,'清單'!$B$4:$B$26,'清單'!I4:I26,0,1,1)} -> 道具消除 | J5: {=XLOOKUP($A$1,'清單'!$B$4:$B$26,'清單'!J4:J26,0,1,1)} -> Potion Bottle | K5: {=XLOOKUP($A$1,'清單'!$B$4:$B$26,'清單'!K4:K26,0,1,1)} -> 41
A8: 2 | B8: 特性規則
C9: =C4 -> 類型 | D9: 描述
C10: =C5 -> 容器 | D10: {=XLOOKUP($C$5,Glossary!$B:$B,Glossary!$D:$D,1,1,1)} -> 容器障礙物一般來說分成兩個階段，階段1為單次消除打開層級，可能有數層。階段2具有單次消除或多次消除的內容物。
C12: 屬性1 | D12: 描述
C13: =if(ISBLANK($D$5),"無",CONCATENATE($D$5)) -> 複數地塊 | D13: {=if(ISBLANK($D$5),"無",XLOOKUP($D$5,Glossary!B:B,Glossary!D:D,1,1,1))} -> 物件最小存在單位超過一個地塊。
C15: 屬性2 | D15: 描述
C16: =if(ISBLANK($E$5),"無",CONCATENATE($E$5)) -> 對應顏色 | D16: {=if(ISBLANK($E$5),"無",XLOOKUP($E$5,Glossary!B:B,Glossary!D:D,1,1,1))} -> 需要對應顏色的元素消除才能做出有效消除。
C18: 盤面運動 | D18: 描述
C19: =if(ISBLANK($F$5),,CONCATENATE($F$5)) -> 固定 | D19: {=if(ISBLANK($F$5),,XLOOKUP($F$5,Glossary!B:B,Glossary!D:D,1,1,1))} -> 當物件屬性為固定時，代表物件在盤面的位置不會變動，且不會被滑動、交換及掉落。盤面運動屬性為固定的物件，都無法透過生成器生成。
C21: 消除類型 | D21: 描述
C22: =if(ISBLANK($G$5),"無",CONCATENATE($G$5)) -> 單次消除 | D22: {=if(ISBLANK($G$5),"無",XLOOKUP($G$5,Glossary!B:B,Glossary!D:D,1,1,1))} -> 設定為單次消除的層級，在一次消除行為下，只能被消除一次。該次消除行為包含的複數地塊消除，都算是該單次消除行為。
C24: 消除方式1 | D24: 描述
C25: =if(ISBLANK($H$5),"無",CONCATENATE($H$5)) -> 鄰邊消除 | D25: {=if(ISBLANK($H$5),,XLOOKUP($H$5,Glossary!B:B,Glossary!D:D,1,1,1))} -> 在與物件相鄰的地塊觸發消除行為時，會對物件產生消除效果。
C27: 消除方式2 | D27: 描述
C28: =if(ISBLANK($I$5),"無",CONCATENATE($I$5)) -> 道具消除 | D28: {=if(ISBLANK($I$5),,XLOOKUP($I$5,Glossary!B:B,Glossary!D:D,1,1,1))} -> 由道具發出的消除行為，會對物件產生消除效果。
C31: 雞蛋糕台在受到鄰邊消除及道具消除時，會生產對應消除次數的特定通關目標物。
A34: 3 | B34: 特性參數
C35: 編輯器可設定生產物為盤面的通關目標及所需數量
C37: 當對郵戳印章受到消除時，印章會蓋下並生產一張有郵戳的明信片讓玩家收集。
C38: 明信片會彈出後飛往通關資訊區。
C39: 當明信片收集額滿時，郵戳印章會放在地塊上，郵戳下也不再有空白明信片。

Sheet 10.木桶
A1: 木桶 | C1: 靜態圖檔名： | D1: Cookie | H1: 返回清單
A3: 1 | B3: 關鍵字
C4: 類型 | D4: 屬性1 | E4: 屬性2 | F4: 盤面運動 | G4: 消除類型 | H4: 消除方式1 | I4: 消除方式2 | J4: RM對應 | K4: RM初現關卡
C5: {=XLOOKUP($A$1,'清單'!$B$4:$B$26,'清單'!C4:C26,0,1,1)} -> 一般型 | D5: {=XLOOKUP($A$1,'清單'!$B$4:$B$26,'清單'!D4:D26,0,1,1)} -> 對應顏色 | E5: {=XLOOKUP($A$1,'清單'!$B$4:$B$26,'清單'!E4:E26,0,1,1)} -> 特殊屬性 | F5: {=XLOOKUP($A$1,'清單'!$B$4:$B$26,'清單'!F4:F26,0,1,1)} -> 移動 | G5: {=XLOOKUP($A$1,'清單'!$B$4:$B$26,'清單'!G4:G26,0,1,1)} -> 單次消除 | H5: {=XLOOKUP($A$1,'清單'!$B$4:$B$26,'清單'!H4:H26,0,1,1)} -> 鄰邊消除 | I5: {=XLOOKUP($A$1,'清單'!$B$4:$B$26,'清單'!I4:I26,0,1,1)} -> 道具消除 | J5: {=XLOOKUP($A$1,'清單'!$B$4:$B$26,'清單'!J4:J26,0,1,1)} -> https://royalmatch.fandom.com/wiki/Rock | K5: {=XLOOKUP($A$1,'清單'!$B$4:$B$26,'清單'!K4:K26,0,1,1)} -> 261
A8: 2 | B8: 特性規則
C9: =C4 -> 類型 | D9: 描述
C10: =C5 -> 一般型 | D10: {=XLOOKUP($C$5,Glossary!$B:$B,Glossary!$D:$D,1,1,1)} -> 最基礎的障礙物，具備1~N層，主要透過鄰邊消除和道具消除的手段來消除。
C12: 屬性1 | D12: 描述
C13: =if(ISBLANK($D$5),"無",CONCATENATE($D$5)) -> 對應顏色 | D13: {=if(ISBLANK($D$5),"無",XLOOKUP($D$5,Glossary!B:B,Glossary!D:D,1,1,1))} -> 需要對應顏色的元素消除才能做出有效消除。
C15: 屬性2 | D15: 描述
C16: =if(ISBLANK($E$5),"無",CONCATENATE($E$5)) -> 特殊屬性 | D16: {=if(ISBLANK($E$5),"無",XLOOKUP($E$5,Glossary!B:B,Glossary!D:D,1,1,1))} -> 雖然障礙物大致上符合某種類型的劃分，但有局部獨特的效果屬性，在清單中以此做分類，並會在該障礙物文件中詳細闡述。
C18: 盤面運動 | D18: 描述
C19: =if(ISBLANK($F$5),,CONCATENATE($F$5)) -> 移動 | D19: {=if(ISBLANK($F$5),,XLOOKUP($F$5,Glossary!B:B,Glossary!D:D,1,1,1))} -> 物件在盤面上，可被玩家滑動，或因為地形特殊效果和下方地塊沒有物件而位移。此類物件皆可透過生成器生成。
C21: 消除類型 | D21: 描述
C22: =if(ISBLANK($G$5),"無",CONCATENATE($G$5)) -> 單次消除 | D22: {=if(ISBLANK($G$5),"無",XLOOKUP($G$5,Glossary!B:B,Glossary!D:D,1,1,1))} -> 設定為單次消除的層級，在一次消除行為下，只能被消除一次。該次消除行為包含的複數地塊消除，都算是該單次消除行為。
C24: 消除方式1 | D24: 描述
C25: =if(ISBLANK($H$5),"無",CONCATENATE($H$5)) -> 鄰邊消除 | D25: {=if(ISBLANK($H$5),,XLOOKUP($H$5,Glossary!B:B,Glossary!D:D,1,1,1))} -> 在與物件相鄰的地塊觸發消除行為時，會對物件產生消除效果。
C27: 消除方式2 | D27: 描述
C28: =if(ISBLANK($I$5),"無",CONCATENATE($I$5)) -> 道具消除 | D28: {=if(ISBLANK($I$5),,XLOOKUP($I$5,Glossary!B:B,Glossary!D:D,1,1,1))} -> 由道具發出的消除行為，會對物件產生消除效果。
A31: 3 | B31: 特性參數
C32: 餅乾1的層數固定為1。
C34: 編輯器可設定生成器的餅乾1生成機率。
C36: 編輯器可設定單一生成器的餅乾1最大生成數量，預設為無限制。
C38: 編輯器可設定全局餅乾1最大生成數量，預設為無限制。
C40: 編輯器可設定餅乾為盤面的通關目標及所需數量。
C42: 只有一層，受到消除後直接破碎後消失
A45: 4 | B45: 備註
C46: 目前會將部分障礙物，做成不同層數並用不同外形包裝。
C47: 可以節省製作時間並達到視覺上變化的效果。

Sheet 11.藥水櫃
A1: 飲料櫃 | C1: 靜態圖檔名： | D1: 小丸子專案內無類似靜態圖 | H1: 返回清單
A3: 1 | B3: 關鍵字
C4: 類型 | D4: 屬性1 | E4: 屬性2 | F4: 盤面運動 | G4: 消除類型 | H4: 消除方式1 | I4: 消除方式2 | J4: RM對應 | K4: RM初現關卡
C5: {=XLOOKUP($A$1,'清單'!$B$4:$B$26,'清單'!C4:C26,0,1,1)} -> 容器 | D5: {=XLOOKUP($A$1,'清單'!$B$4:$B$26,'清單'!D4:D26,0,1,1)} -> 複數地塊 | E5: {=XLOOKUP($A$1,'清單'!$B$4:$B$26,'清單'!E4:E26,0,1,1)} -> 對應顏色 | F5: {=XLOOKUP($A$1,'清單'!$B$4:$B$26,'清單'!F4:F26,0,1,1)} -> 固定 | G5: {=XLOOKUP($A$1,'清單'!$B$4:$B$26,'清單'!G4:G26,0,1,1)} -> 單次消除 | H5: {=XLOOKUP($A$1,'清單'!$B$4:$B$26,'清單'!H4:H26,0,1,1)} -> 鄰邊消除 | I5: {=XLOOKUP($A$1,'清單'!$B$4:$B$26,'清單'!I4:I26,0,1,1)} -> 道具消除 | J5: {=XLOOKUP($A$1,'清單'!$B$4:$B$26,'清單'!J4:J26,0,1,1)} -> Potion Bottle | K5: {=XLOOKUP($A$1,'清單'!$B$4:$B$26,'清單'!K4:K26,0,1,1)} -> 41
A8: 2 | B8: 特性規則
C9: =C4 -> 類型 | D9: 描述
C10: =C5 -> 容器 | D10: {=XLOOKUP($C$5,Glossary!$B:$B,Glossary!$D:$D,1,1,1)} -> 容器障礙物一般來說分成兩個階段，階段1為單次消除打開層級，可能有數層。階段2具有單次消除或多次消除的內容物。
C12: 屬性1 | D12: 描述
C13: =if(ISBLANK($D$5),"無",CONCATENATE($D$5)) -> 複數地塊 | D13: {=if(ISBLANK($D$5),"無",XLOOKUP($D$5,Glossary!B:B,Glossary!D:D,1,1,1))} -> 物件最小存在單位超過一個地塊。
C15: 屬性2 | D15: 描述
C16: =if(ISBLANK($E$5),"無",CONCATENATE($E$5)) -> 對應顏色 | D16: {=if(ISBLANK($E$5),"無",XLOOKUP($E$5,Glossary!B:B,Glossary!D:D,1,1,1))} -> 需要對應顏色的元素消除才能做出有效消除。
C18: 盤面運動 | D18: 描述
C19: =if(ISBLANK($F$5),,CONCATENATE($F$5)) -> 固定 | D19: {=if(ISBLANK($F$5),,XLOOKUP($F$5,Glossary!B:B,Glossary!D:D,1,1,1))} -> 當物件屬性為固定時，代表物件在盤面的位置不會變動，且不會被滑動、交換及掉落。盤面運動屬性為固定的物件，都無法透過生成器生成。
C21: 消除類型 | D21: 描述
C22: =if(ISBLANK($G$5),"無",CONCATENATE($G$5)) -> 單次消除 | D22: {=if(ISBLANK($G$5),"無",XLOOKUP($G$5,Glossary!B:B,Glossary!D:D,1,1,1))} -> 設定為單次消除的層級，在一次消除行為下，只能被消除一次。該次消除行為包含的複數地塊消除，都算是該單次消除行為。
C24: 消除方式1 | D24: 描述
C25: =if(ISBLANK($H$5),"無",CONCATENATE($H$5)) -> 鄰邊消除 | D25: {=if(ISBLANK($H$5),,XLOOKUP($H$5,Glossary!B:B,Glossary!D:D,1,1,1))} -> 在與物件相鄰的地塊觸發消除行為時，會對物件產生消除效果。
C27: 消除方式2 | D27: 描述
C28: =if(ISBLANK($I$5),"無",CONCATENATE($I$5)) -> 道具消除 | D28: {=if(ISBLANK($I$5),,XLOOKUP($I$5,Glossary!B:B,Glossary!D:D,1,1,1))} -> 由道具發出的消除行為，會對物件產生消除效果。
C31: 藥水櫃內的藥水瓶數量固定為4瓶。
C33: 藥水櫃分為兩個層級，第一層是櫃子關閉狀態，第二層是櫃子打開狀態：
D34: 第一層-櫃子關閉
E35: 此時藥水櫃為單次消除，消除1次後櫃子打開。
D37: 第二層-櫃子打開
E38: 此時藥水櫃仍為單次消除。
E39: 在飲料櫃周圍消除元素，可消除櫃內對應元素顏色的飲料瓶。
E40: 若使用道具消除，則隨機則一藥水消除。
E41: 在全部藥水消除後，藥水櫃也消除在盤面上。
A44: 3 | B44: 特性參數
C45: 可編輯需要消除的藥水的顏色。
C47: 初始預設藥水櫃內的藥水顏色為元素顏色0、1、2、3各1瓶
C49: 藥水的順序按照ID大小，由左上至右下排列。
C51: 受道具消除時的順序為隨機決定。
C53: 編輯器可設定藥水櫃為盤面的通關目標及所需數量。
C55: 第一層，櫃門消失，櫃子成開放式狀態，陳設的四色飲料瓶可被消除。
C56: 消除時，四色飲料會彈出後飛往通關資訊區。
C57: 櫃內的飲料都按照紅、綠、黃、藍顏色陳列，共4瓶，陳列方式可參考右側櫥櫃內的盤子擺放方式。
C59: 第二層，飲料櫃有透明櫃門，被消除時櫃門會彈飛。

Sheet 12.交通錐
A1: 交通錐 | C1: 靜態圖檔名： | D1: 小丸子專案內無類似靜態圖 | H1: 返回清單
A3: 1 | B3: 關鍵字
C4: 類型 | D4: 屬性1 | E4: 屬性2 | F4: 盤面運動 | G4: 消除類型 | H4: 消除方式1 | I4: 消除方式2 | J4: RM對應 | K4: RM初現關卡
C5: {=XLOOKUP($A$1,'清單'!$B$4:$B$26,'清單'!C4:C26,0,1,1)} -> 容器 | D5: {=XLOOKUP($A$1,'清單'!$B$4:$B$26,'清單'!D4:D26,0,1,1)} -> 複數地塊 | E5: {=XLOOKUP($A$1,'清單'!$B$4:$B$26,'清單'!E4:E26,0,1,1)} -> 特殊屬性 | F5: {=XLOOKUP($A$1,'清單'!$B$4:$B$26,'清單'!F4:F26,0,1,1)} -> 固定 | G5: {=XLOOKUP($A$1,'清單'!$B$4:$B$26,'清單'!G4:G26,0,1,1)} -> 混合消除 | H5: {=XLOOKUP($A$1,'清單'!$B$4:$B$26,'清單'!H4:H26,0,1,1)} -> 鄰邊消除 | I5: {=XLOOKUP($A$1,'清單'!$B$4:$B$26,'清單'!I4:I26,0,1,1)} -> 道具消除 | J5: {=XLOOKUP($A$1,'清單'!$B$4:$B$26,'清單'!J4:J26,0,1,1)} | K5: {=XLOOKUP($A$1,'清單'!$B$4:$B$26,'清單'!K4:K26,0,1,1)} -> 401
A8: 2 | B8: 特性規則
C9: =C4 -> 類型 | D9: 描述
C10: =C5 -> 容器 | D10: {=XLOOKUP($C$5,Glossary!$B:$B,Glossary!$D:$D,1,1,1)} -> 容器障礙物一般來說分成兩個階段，階段1為單次消除打開層級，可能有數層。階段2具有單次消除或多次消除的內容物。
C12: 屬性1 | D12: 描述
C13: =if(ISBLANK($D$5),"無",CONCATENATE($D$5)) -> 複數地塊 | D13: {=if(ISBLANK($D$5),"無",XLOOKUP($D$5,Glossary!B:B,Glossary!D:D,1,1,1))} -> 物件最小存在單位超過一個地塊。
C15: 屬性2 | D15: 描述
C16: =if(ISBLANK($E$5),"無",CONCATENATE($E$5)) -> 特殊屬性 | D16: {=if(ISBLANK($E$5),"無",XLOOKUP($E$5,Glossary!B:B,Glossary!D:D,1,1,1))} -> 雖然障礙物大致上符合某種類型的劃分，但有局部獨特的效果屬性，在清單中以此做分類，並會在該障礙物文件中詳細闡述。
C18: 盤面運動 | D18: 描述
C19: =if(ISBLANK($F$5),,CONCATENATE($F$5)) -> 固定 | D19: {=if(ISBLANK($F$5),,XLOOKUP($F$5,Glossary!B:B,Glossary!D:D,1,1,1))} -> 當物件屬性為固定時，代表物件在盤面的位置不會變動，且不會被滑動、交換及掉落。盤面運動屬性為固定的物件，都無法透過生成器生成。
C21: 消除類型 | D21: 描述
C22: =if(ISBLANK($G$5),"無",CONCATENATE($G$5)) -> 混合消除 | D22: {=if(ISBLANK($G$5),"無",XLOOKUP($G$5,Glossary!B:B,Glossary!D:D,1,1,1))} -> 單一障礙物的不同層級，存在單次消除和多次消除的設定，定義為混合消除。避免設計者混淆。
C24: 消除方式1 | D24: 描述
C25: =if(ISBLANK($H$5),"無",CONCATENATE($H$5)) -> 鄰邊消除 | D25: {=if(ISBLANK($H$5),,XLOOKUP($H$5,Glossary!B:B,Glossary!D:D,1,1,1))} -> 在與物件相鄰的地塊觸發消除行為時，會對物件產生消除效果。
C27: 消除方式2 | D27: 描述
C28: =if(ISBLANK($I$5),"無",CONCATENATE($I$5)) -> 道具消除 | D28: {=if(ISBLANK($I$5),,XLOOKUP($I$5,Glossary!B:B,Glossary!D:D,1,1,1))} -> 由道具發出的消除行為，會對物件產生消除效果。
A31: 3 | B31: 特性參數
C32: 交通錐的層數可設定為1或2。
C34: 層數為1的交通錐沒有燈，層數為2的交通錐有燈。
C36: 編輯器可設定生成器的交通錐生成機率。
C38: 編輯器可設定單一生成器的交通錐最大生成數量，預設為無限制。
C40: 編輯器可設定全局交通錐最大生成數量，預設為無限制。
C42: 編輯器可設定交通錐為盤面的通關目標及所需數量。
C44: 第一層，單一交通錐，消除時交通錐破碎消失。
C45: 第二層，交通錐上有一個警示燈，消除時警示燈會噴掉。
A49: 4 | B49: 備註
C50: 目前會將部分障礙物，做成不同層數並用不同外形包裝。
C51: 可以節省製作時間並達到視覺上變化的效果。

Sheet 路障
A1: 路障 | C1: 靜態圖檔名： | D1: 小丸子專案內無類似靜態圖 | H1: 返回清單
A3: 1 | B3: 關鍵字
C4: 類型 | D4: 屬性1 | E4: 屬性2 | F4: 盤面運動 | G4: 消除類型 | H4: 消除方式1 | I4: 消除方式2 | J4: RM對應 | K4: RM初現關卡
C5: {=XLOOKUP($A$1,'清單'!$B$4:$B$26,'清單'!C4:C26,0,1,1)} -> 一般型 | D5: {=XLOOKUP($A$1,'清單'!$B$4:$B$26,'清單'!D4:D26,0,1,1)} | E5: {=XLOOKUP($A$1,'清單'!$B$4:$B$26,'清單'!E4:E26,0,1,1)} | F5: {=XLOOKUP($A$1,'清單'!$B$4:$B$26,'清單'!F4:F26,0,1,1)} -> 移動 | G5: {=XLOOKUP($A$1,'清單'!$B$4:$B$26,'清單'!G4:G26,0,1,1)} -> 單次消除 | H5: {=XLOOKUP($A$1,'清單'!$B$4:$B$26,'清單'!H4:H26,0,1,1)} -> 鄰邊消除 | I5: {=XLOOKUP($A$1,'清單'!$B$4:$B$26,'清單'!I4:I26,0,1,1)} -> 道具消除 | J5: {=XLOOKUP($A$1,'清單'!$B$4:$B$26,'清單'!J4:J26,0,1,1)} -> Vase | K5: {=XLOOKUP($A$1,'清單'!$B$4:$B$26,'清單'!K4:K26,0,1,1)} -> 51
A8: 2 | B8: 特性規則
C9: =C4 -> 類型 | D9: 描述
C10: =C5 -> 一般型 | D10: {=XLOOKUP($C$5,Glossary!$B:$B,Glossary!$D:$D,1,1,1)} -> 最基礎的障礙物，具備1~N層，主要透過鄰邊消除和道具消除的手段來消除。
C12: 屬性1 | D12: 描述
C13: =if(ISBLANK($D$5),"無",CONCATENATE($D$5)) -> 無 | D13: {=if(ISBLANK($D$5),"無",XLOOKUP($D$5,Glossary!B:B,Glossary!D:D,1,1,1))} -> 無
C15: 屬性2 | D15: 描述
C16: =if(ISBLANK($E$5),"無",CONCATENATE($E$5)) -> 無 | D16: {=if(ISBLANK($E$5),"無",XLOOKUP($E$5,Glossary!B:B,Glossary!D:D,1,1,1))} -> 無
C18: 盤面運動 | D18: 描述
C19: =if(ISBLANK($F$5),,CONCATENATE($F$5)) -> 移動 | D19: {=if(ISBLANK($F$5),,XLOOKUP($F$5,Glossary!B:B,Glossary!D:D,1,1,1))} -> 物件在盤面上，可被玩家滑動，或因為地形特殊效果和下方地塊沒有物件而位移。此類物件皆可透過生成器生成。
C21: 消除類型 | D21: 描述
C22: =if(ISBLANK($G$5),"無",CONCATENATE($G$5)) -> 單次消除 | D22: {=if(ISBLANK($G$5),"無",XLOOKUP($G$5,Glossary!B:B,Glossary!D:D,1,1,1))} -> 設定為單次消除的層級，在一次消除行為下，只能被消除一次。該次消除行為包含的複數地塊消除，都算是該單次消除行為。
C24: 消除方式1 | D24: 描述
C25: =if(ISBLANK($H$5),"無",CONCATENATE($H$5)) -> 鄰邊消除 | D25: {=if(ISBLANK($H$5),,XLOOKUP($H$5,Glossary!B:B,Glossary!D:D,1,1,1))} -> 在與物件相鄰的地塊觸發消除行為時，會對物件產生消除效果。
C27: 消除方式2 | D27: 描述
C28: =if(ISBLANK($I$5),"無",CONCATENATE($I$5)) -> 道具消除 | D28: {=if(ISBLANK($I$5),,XLOOKUP($I$5,Glossary!B:B,Glossary!D:D,1,1,1))} -> 由道具發出的消除行為，會對物件產生消除效果。
A31: 3 | B31: 特性參數
C32: 路障的層數固定為2。
C34: 編輯器可設定生成器的路障生成機率。
C36: 編輯器可設定單一生成器的路障最大生成數量，預設為無限制。
C38: 編輯器可設定全局路障最大生成數量，預設為無限制。
C40: 編輯器可設定路障為盤面的通關目標及所需數量。
C42: 第一層，路障會變成金屬板子被撞到的凹陷+破損狀態，被消除會被擊飛或支解。
C43: 第二層，路障完好狀態。
A47: 4 | B47: 備註
C48: 目前會將部分障礙物，做成不同層數並用不同外形包裝。
C49: 可以節省製作時間並達到視覺上變化的效果。

Sheet 13.罐頭
A1: 罐頭 | C1: 靜態圖檔名： | D1: Gem | H1: 返回清單
A3: 1 | B3: 關鍵字
C4: 類型 | D4: 屬性1 | E4: 屬性2 | F4: 盤面運動 | G4: 消除類型 | H4: 消除方式1 | I4: 消除方式2 | J4: RM對應 | K4: RM初現關卡
C5: {=XLOOKUP($A$1,'清單'!$B$4:$B$26,'清單'!C4:C26,0,1,1)} -> 一般型 | D5: {=XLOOKUP($A$1,'清單'!$B$4:$B$26,'清單'!D4:D26,0,1,1)} | E5: {=XLOOKUP($A$1,'清單'!$B$4:$B$26,'清單'!E4:E26,0,1,1)} | F5: {=XLOOKUP($A$1,'清單'!$B$4:$B$26,'清單'!F4:F26,0,1,1)} -> 固定 | G5: {=XLOOKUP($A$1,'清單'!$B$4:$B$26,'清單'!G4:G26,0,1,1)} -> 單次消除 | H5: {=XLOOKUP($A$1,'清單'!$B$4:$B$26,'清單'!H4:H26,0,1,1)} -> 道具消除 | I5: {=XLOOKUP($A$1,'清單'!$B$4:$B$26,'清單'!I4:I26,0,1,1)} | J5: {=XLOOKUP($A$1,'清單'!$B$4:$B$26,'清單'!J4:J26,0,1,1)} -> Owl | K5: {=XLOOKUP($A$1,'清單'!$B$4:$B$26,'清單'!K4:K26,0,1,1)} -> 61
A8: 2 | B8: 特性規則
C9: =C4 -> 類型 | D9: 描述
C10: =C5 -> 一般型 | D10: {=XLOOKUP($C$5,Glossary!$B:$B,Glossary!$D:$D,1,1,1)} -> 最基礎的障礙物，具備1~N層，主要透過鄰邊消除和道具消除的手段來消除。
C12: 屬性1 | D12: 描述
C13: =if(ISBLANK($D$5),"無",CONCATENATE($D$5)) -> 無 | D13: {=if(ISBLANK($D$5),"無",XLOOKUP($D$5,Glossary!B:B,Glossary!D:D,1,1,1))} -> 無
C15: 屬性2 | D15: 描述
C16: =if(ISBLANK($E$5),"無",CONCATENATE($E$5)) -> 無 | D16: {=if(ISBLANK($E$5),"無",XLOOKUP($E$5,Glossary!B:B,Glossary!D:D,1,1,1))} -> 無
C18: 盤面運動 | D18: 描述
C19: =if(ISBLANK($F$5),,CONCATENATE($F$5)) -> 固定 | D19: {=if(ISBLANK($F$5),,XLOOKUP($F$5,Glossary!B:B,Glossary!D:D,1,1,1))} -> 當物件屬性為固定時，代表物件在盤面的位置不會變動，且不會被滑動、交換及掉落。盤面運動屬性為固定的物件，都無法透過生成器生成。
C21: 消除類型 | D21: 描述
C22: =if(ISBLANK($G$5),"無",CONCATENATE($G$5)) -> 單次消除 | D22: {=if(ISBLANK($G$5),"無",XLOOKUP($G$5,Glossary!B:B,Glossary!D:D,1,1,1))} -> 設定為單次消除的層級，在一次消除行為下，只能被消除一次。該次消除行為包含的複數地塊消除，都算是該單次消除行為。
C24: 消除方式1 | D24: 描述
C25: =if(ISBLANK($H$5),"無",CONCATENATE($H$5)) -> 道具消除 | D25: {=if(ISBLANK($H$5),,XLOOKUP($H$5,Glossary!B:B,Glossary!D:D,1,1,1))} -> 由道具發出的消除行為，會對物件產生消除效果。
C27: 消除方式2 | D27: 描述
C28: =if(ISBLANK($I$5),"無",CONCATENATE($I$5)) -> 無 | D28: {=if(ISBLANK($I$5),,XLOOKUP($I$5,Glossary!B:B,Glossary!D:D,1,1,1))}
A31: 3 | B31: 特性參數
C32: 編輯器可設定寶石1的層數為1~3層。
C34: 編輯器可設定寶石1為盤面的通關目標及所需數量。
C36: 第一層，罐頭易拉環會被拉起或是罐頭受到擠壓(EX:大力水手開菠菜)。
C37: 第二層，正常罐頭外觀，有罐頭內容物的標籤在罐頭上。
A41: 4 | B41: 備註
C42: 目前會將部分障礙物，做成不同層數並用不同外形包裝。
C43: 可以節省製作時間並達到視覺上變化的效果。

Sheet 14.充氣游泳池
A1: 充氣游泳池 | C1: 靜態圖檔名： | D1: 小丸子專案內無類似靜態圖 | H1: 返回清單
A3: 1 | B3: 關鍵字
C4: 類型 | D4: 屬性1 | E4: 屬性2 | F4: 盤面運動 | G4: 消除類型 | H4: 消除方式1 | I4: 消除方式2 | J4: RM對應 | K4: RM初現關卡
C5: {=XLOOKUP($A$1,'清單'!$B$4:$B$26,'清單'!C4:C26,0,1,1)} -> 一般型 | D5: {=XLOOKUP($A$1,'清單'!$B$4:$B$26,'清單'!D4:D26,0,1,1)} -> 複數地塊 | E5: {=XLOOKUP($A$1,'清單'!$B$4:$B$26,'清單'!E4:E26,0,1,1)} | F5: {=XLOOKUP($A$1,'清單'!$B$4:$B$26,'清單'!F4:F26,0,1,1)} -> 固定 | G5: {=XLOOKUP($A$1,'清單'!$B$4:$B$26,'清單'!G4:G26,0,1,1)} -> 單次消除 | H5: {=XLOOKUP($A$1,'清單'!$B$4:$B$26,'清單'!H4:H26,0,1,1)} -> 鄰邊消除 | I5: {=XLOOKUP($A$1,'清單'!$B$4:$B$26,'清單'!I4:I26,0,1,1)} -> 道具消除 | J5: {=XLOOKUP($A$1,'清單'!$B$4:$B$26,'清單'!J4:J26,0,1,1)} -> Bush | K5: {=XLOOKUP($A$1,'清單'!$B$4:$B$26,'清單'!K4:K26,0,1,1)} -> 71
A8: 2 | B8: 特性規則
C9: =C4 -> 類型 | D9: 描述
C10: =C5 -> 一般型 | D10: {=XLOOKUP($C$5,Glossary!$B:$B,Glossary!$D:$D,1,1,1)} -> 最基礎的障礙物，具備1~N層，主要透過鄰邊消除和道具消除的手段來消除。
C12: 屬性1 | D12: 描述
C13: =if(ISBLANK($D$5),"無",CONCATENATE($D$5)) -> 複數地塊 | D13: {=if(ISBLANK($D$5),"無",XLOOKUP($D$5,Glossary!B:B,Glossary!D:D,1,1,1))} -> 物件最小存在單位超過一個地塊。
C15: 屬性2 | D15: 描述
C16: =if(ISBLANK($E$5),"無",CONCATENATE($E$5)) -> 無 | D16: {=if(ISBLANK($E$5),"無",XLOOKUP($E$5,Glossary!B:B,Glossary!D:D,1,1,1))} -> 無
C18: 盤面運動 | D18: 描述
C19: =if(ISBLANK($F$5),,CONCATENATE($F$5)) -> 固定 | D19: {=if(ISBLANK($F$5),,XLOOKUP($F$5,Glossary!B:B,Glossary!D:D,1,1,1))} -> 當物件屬性為固定時，代表物件在盤面的位置不會變動，且不會被滑動、交換及掉落。盤面運動屬性為固定的物件，都無法透過生成器生成。
C21: 消除類型 | D21: 描述
C22: =if(ISBLANK($G$5),"無",CONCATENATE($G$5)) -> 單次消除 | D22: {=if(ISBLANK($G$5),"無",XLOOKUP($G$5,Glossary!B:B,Glossary!D:D,1,1,1))} -> 設定為單次消除的層級，在一次消除行為下，只能被消除一次。該次消除行為包含的複數地塊消除，都算是該單次消除行為。
C24: 消除方式1 | D24: 描述
C25: =if(ISBLANK($H$5),"無",CONCATENATE($H$5)) -> 鄰邊消除 | D25: {=if(ISBLANK($H$5),,XLOOKUP($H$5,Glossary!B:B,Glossary!D:D,1,1,1))} -> 在與物件相鄰的地塊觸發消除行為時，會對物件產生消除效果。
C27: 消除方式2 | D27: 描述
C28: =if(ISBLANK($I$5),"無",CONCATENATE($I$5)) -> 道具消除 | D28: {=if(ISBLANK($I$5),,XLOOKUP($I$5,Glossary!B:B,Glossary!D:D,1,1,1))} -> 由道具發出的消除行為，會對物件產生消除效果。
A31: 3 | B31: 特性參數
C32: 草叢層數固定為5層。
C34: 草叢尺寸固定為2*2地塊。
C36: 草叢每層的外型都會有變化。
C38: 編輯器可設定草叢為盤面的通關目標及所需數量。
C40: 5層變化分別是
C41: 第一層，空的充氣泳池
C42: 第二層，有水的充氣泳池
C43: 第三層，有一個游泳圈的有水充氣泳池
C44: 第四層，有兩個游泳圈的有水充氣泳池
C45: 第五層，有三個游泳圈的有水充氣泳池
C46: 每層被消除時，都會撥放消除特效後，降階為下一層。

Sheet 15.繩索
A1: 繩索 | C1: 靜態圖檔名： | D1: Chain | H1: 返回清單
A3: 1 | B3: 關鍵字
C4: 類型 | D4: 屬性1 | E4: 屬性2 | F4: 盤面運動 | G4: 消除類型 | H4: 消除方式1 | I4: 消除方式2 | J4: RM對應 | K4: RM初現關卡
C5: {=XLOOKUP($A$1,'清單'!$B$4:$B$26,'清單'!C4:C26,0,1,1)} -> 上層型 | D5: {=XLOOKUP($A$1,'清單'!$B$4:$B$26,'清單'!D4:D26,0,1,1)} -> 特殊屬性 | E5: {=XLOOKUP($A$1,'清單'!$B$4:$B$26,'清單'!E4:E26,0,1,1)} | F5: {=XLOOKUP($A$1,'清單'!$B$4:$B$26,'清單'!F4:F26,0,1,1)} -> 固定 | G5: {=XLOOKUP($A$1,'清單'!$B$4:$B$26,'清單'!G4:G26,0,1,1)} -> 單次消除 | H5: {=XLOOKUP($A$1,'清單'!$B$4:$B$26,'清單'!H4:H26,0,1,1)} -> 道具消除 | I5: {=XLOOKUP($A$1,'清單'!$B$4:$B$26,'清單'!I4:I26,0,1,1)} -> 原地消除 | J5: {=XLOOKUP($A$1,'清單'!$B$4:$B$26,'清單'!J4:J26,0,1,1)} -> Chain | K5: {=XLOOKUP($A$1,'清單'!$B$4:$B$26,'清單'!K4:K26,0,1,1)} -> 951
A8: 2 | B8: 特性規則
C9: =C4 -> 類型 | D9: 描述
C10: =C5 -> 上層型 | D10: {=XLOOKUP($C$5,Glossary!$B:$B,Glossary!$D:$D,1,1,1)} -> 上層型障礙物可以覆蓋於其他的障礙物之上(不可覆蓋於其他上層型障礙物)，當上層型障礙物存在時，無法被其覆蓋的其他障礙物。
C12: 屬性1 | D12: 描述
C13: =if(ISBLANK($D$5),"無",CONCATENATE($D$5)) -> 特殊屬性 | D13: {=if(ISBLANK($D$5),"無",XLOOKUP($D$5,Glossary!B:B,Glossary!D:D,1,1,1))} -> 雖然障礙物大致上符合某種類型的劃分，但有局部獨特的效果屬性，在清單中以此做分類，並會在該障礙物文件中詳細闡述。
C15: 屬性2 | D15: 描述
C16: =if(ISBLANK($E$5),"無",CONCATENATE($E$5)) -> 無 | D16: {=if(ISBLANK($E$5),"無",XLOOKUP($E$5,Glossary!B:B,Glossary!D:D,1,1,1))} -> 無
C18: 盤面運動 | D18: 描述
C19: =if(ISBLANK($F$5),,CONCATENATE($F$5)) -> 固定 | D19: {=if(ISBLANK($F$5),,XLOOKUP($F$5,Glossary!B:B,Glossary!D:D,1,1,1))} -> 當物件屬性為固定時，代表物件在盤面的位置不會變動，且不會被滑動、交換及掉落。盤面運動屬性為固定的物件，都無法透過生成器生成。
C21: 消除類型 | D21: 描述
C22: =if(ISBLANK($G$5),"無",CONCATENATE($G$5)) -> 單次消除 | D22: {=if(ISBLANK($G$5),"無",XLOOKUP($G$5,Glossary!B:B,Glossary!D:D,1,1,1))} -> 設定為單次消除的層級，在一次消除行為下，只能被消除一次。該次消除行為包含的複數地塊消除，都算是該單次消除行為。
C24: 消除方式1 | D24: 描述
C25: =if(ISBLANK($H$5),"無",CONCATENATE($H$5)) -> 道具消除 | D25: {=if(ISBLANK($H$5),,XLOOKUP($H$5,Glossary!B:B,Glossary!D:D,1,1,1))} -> 由道具發出的消除行為，會對物件產生消除效果。
C27: 消除方式2 | D27: 描述
C28: =if(ISBLANK($I$5),"無",CONCATENATE($I$5)) -> 原地消除 | D28: {=if(ISBLANK($I$5),,XLOOKUP($I$5,Glossary!B:B,Glossary!D:D,1,1,1))} -> 在同一個地塊上，由基本元素拼湊後觸發的消除，會對物件產生消除效果。
C31: 屬性1註解 | D31: 繩索覆蓋下層物件後，會使下層物件無法被移動和使用，
D32: 但被繩索覆蓋的基礎元素，仍然可與周圍的基礎元素拼湊成同色消除。
D33: 在拼湊成同色消除時，被覆蓋的元素不會被消除，但可以對繩索造成1層消除，
D34: 且如果符合生成道具的條件，道具可以正常生成於盤面上。
A37: 3 | B37: 特性參數
C38: 編輯器可設定繩索層數1~2層。 | E38: (Royal Match固定層數為1)
C40: 繩索每層的外型都會有變化。 | E40: ╲ > ╳
C42: 編輯器可設定繩索為盤面的通關目標及所需數量。
C44: 第一層繩索是左上到右下固定住物件 第二層繩索增加一條右上到左下，形成X型固定住物件 被消除時會撥放繩索斷裂的特效，並降到下一層。

Sheet 16.泥巴
A1: 泥巴 | C1: 靜態圖檔名： | D1: Honey | H1: 返回清單
A3: 1 | B3: 關鍵字
C4: 類型 | D4: 屬性1 | E4: 屬性2 | F4: 盤面運動 | G4: 消除類型 | H4: 消除方式1 | I4: 消除方式2 | J4: RM對應 | K4: RM初現關卡
C5: {=XLOOKUP($A$1,'清單'!$B$4:$B$26,'清單'!C4:C26,0,1,1)} -> 上層型 | D5: {=XLOOKUP($A$1,'清單'!$B$4:$B$26,'清單'!D4:D26,0,1,1)} | E5: {=XLOOKUP($A$1,'清單'!$B$4:$B$26,'清單'!E4:E26,0,1,1)} | F5: {=XLOOKUP($A$1,'清單'!$B$4:$B$26,'清單'!F4:F26,0,1,1)} -> 固定 | G5: {=XLOOKUP($A$1,'清單'!$B$4:$B$26,'清單'!G4:G26,0,1,1)} -> 單次消除 | H5: {=XLOOKUP($A$1,'清單'!$B$4:$B$26,'清單'!H4:H26,0,1,1)} -> 鄰邊消除 | I5: {=XLOOKUP($A$1,'清單'!$B$4:$B$26,'清單'!I4:I26,0,1,1)} -> 道具消除 | J5: {=XLOOKUP($A$1,'清單'!$B$4:$B$26,'清單'!J4:J26,0,1,1)} -> Honey | K5: {=XLOOKUP($A$1,'清單'!$B$4:$B$26,'清單'!K4:K26,0,1,1)} -> 81
A8: 2 | B8: 特性規則
C9: =C4 -> 類型 | D9: 描述
C10: =C5 -> 上層型 | D10: {=XLOOKUP($C$5,Glossary!$B:$B,Glossary!$D:$D,1,1,1)} -> 上層型障礙物可以覆蓋於其他的障礙物之上(不可覆蓋於其他上層型障礙物)，當上層型障礙物存在時，無法被其覆蓋的其他障礙物。
C12: 屬性1 | D12: 描述
C13: =if(ISBLANK($D$5),"無",CONCATENATE($D$5)) -> 無 | D13: {=if(ISBLANK($D$5),"無",XLOOKUP($D$5,Glossary!B:B,Glossary!D:D,1,1,1))} -> 無
C15: 屬性2 | D15: 描述
C16: =if(ISBLANK($E$5),"無",CONCATENATE($E$5)) -> 無 | D16: {=if(ISBLANK($E$5),"無",XLOOKUP($E$5,Glossary!B:B,Glossary!D:D,1,1,1))} -> 無
C18: 盤面運動 | D18: 描述
C19: =if(ISBLANK($F$5),,CONCATENATE($F$5)) -> 固定 | D19: {=if(ISBLANK($F$5),,XLOOKUP($F$5,Glossary!B:B,Glossary!D:D,1,1,1))} -> 當物件屬性為固定時，代表物件在盤面的位置不會變動，且不會被滑動、交換及掉落。盤面運動屬性為固定的物件，都無法透過生成器生成。
C21: 消除類型 | D21: 描述
C22: =if(ISBLANK($G$5),"無",CONCATENATE($G$5)) -> 單次消除 | D22: {=if(ISBLANK($G$5),"無",XLOOKUP($G$5,Glossary!B:B,Glossary!D:D,1,1,1))} -> 設定為單次消除的層級，在一次消除行為下，只能被消除一次。該次消除行為包含的複數地塊消除，都算是該單次消除行為。
C24: 消除方式1 | D24: 描述
C25: =if(ISBLANK($H$5),"無",CONCATENATE($H$5)) -> 鄰邊消除 | D25: {=if(ISBLANK($H$5),,XLOOKUP($H$5,Glossary!B:B,Glossary!D:D,1,1,1))} -> 在與物件相鄰的地塊觸發消除行為時，會對物件產生消除效果。
C27: 消除方式2 | D27: 描述
C28: =if(ISBLANK($I$5),"無",CONCATENATE($I$5)) -> 道具消除 | D28: {=if(ISBLANK($I$5),,XLOOKUP($I$5,Glossary!B:B,Glossary!D:D,1,1,1))} -> 由道具發出的消除行為，會對物件產生消除效果。
A31: 3 | B31: 特性參數
C32: 泥巴層數固定為1層。

Sheet 17.保險箱
A1: 保險箱 | C1: 靜態圖檔名： | D1: 小丸子專案內無類似靜態圖 | H1: 返回清單
A3: 1 | B3: 關鍵字
C4: 類型 | D4: 屬性1 | E4: 屬性2 | F4: 盤面運動 | G4: 消除類型 | H4: 消除方式1 | I4: 消除方式2 | J4: RM對應 | K4: RM初現關卡
C5: {=XLOOKUP($A$1,'清單'!$B$4:$B$26,'清單'!C4:C26,0,1,1)} -> 一般型 | D5: {=XLOOKUP($A$1,'清單'!$B$4:$B$26,'清單'!D4:D26,0,1,1)} | E5: {=XLOOKUP($A$1,'清單'!$B$4:$B$26,'清單'!E4:E26,0,1,1)} | F5: {=XLOOKUP($A$1,'清單'!$B$4:$B$26,'清單'!F4:F26,0,1,1)} -> 固定 | G5: {=XLOOKUP($A$1,'清單'!$B$4:$B$26,'清單'!G4:G26,0,1,1)} -> 單次消除 | H5: {=XLOOKUP($A$1,'清單'!$B$4:$B$26,'清單'!H4:H26,0,1,1)} -> 道具消除 | I5: {=XLOOKUP($A$1,'清單'!$B$4:$B$26,'清單'!I4:I26,0,1,1)} | J5: {=XLOOKUP($A$1,'清單'!$B$4:$B$26,'清單'!J4:J26,0,1,1)} -> Safe | K5: {=XLOOKUP($A$1,'清單'!$B$4:$B$26,'清單'!K4:K26,0,1,1)} -> 91
A8: 2 | B8: 特性規則
C9: =C4 -> 類型 | D9: 描述
C10: =C5 -> 一般型 | D10: {=XLOOKUP($C$5,Glossary!$B:$B,Glossary!$D:$D,1,1,1)} -> 最基礎的障礙物，具備1~N層，主要透過鄰邊消除和道具消除的手段來消除。
C12: 屬性1 | D12: 描述
C13: =if(ISBLANK($D$5),"無",CONCATENATE($D$5)) -> 無 | D13: {=if(ISBLANK($D$5),"無",XLOOKUP($D$5,Glossary!B:B,Glossary!D:D,1,1,1))} -> 無
C15: 屬性2 | D15: 描述
C16: =if(ISBLANK($E$5),"無",CONCATENATE($E$5)) -> 無 | D16: {=if(ISBLANK($E$5),"無",XLOOKUP($E$5,Glossary!B:B,Glossary!D:D,1,1,1))} -> 無
C18: 盤面運動 | D18: 描述
C19: =if(ISBLANK($F$5),,CONCATENATE($F$5)) -> 固定 | D19: {=if(ISBLANK($F$5),,XLOOKUP($F$5,Glossary!B:B,Glossary!D:D,1,1,1))} -> 當物件屬性為固定時，代表物件在盤面的位置不會變動，且不會被滑動、交換及掉落。盤面運動屬性為固定的物件，都無法透過生成器生成。
C21: 消除類型 | D21: 描述
C22: =if(ISBLANK($G$5),"無",CONCATENATE($G$5)) -> 單次消除 | D22: {=if(ISBLANK($G$5),"無",XLOOKUP($G$5,Glossary!B:B,Glossary!D:D,1,1,1))} -> 設定為單次消除的層級，在一次消除行為下，只能被消除一次。該次消除行為包含的複數地塊消除，都算是該單次消除行為。
C24: 消除方式1 | D24: 描述
C25: =if(ISBLANK($H$5),"無",CONCATENATE($H$5)) -> 道具消除 | D25: {=if(ISBLANK($H$5),,XLOOKUP($H$5,Glossary!B:B,Glossary!D:D,1,1,1))} -> 由道具發出的消除行為，會對物件產生消除效果。
C27: 消除方式2 | D27: 描述
C28: =if(ISBLANK($I$5),"無",CONCATENATE($I$5)) -> 無 | D28: {=if(ISBLANK($I$5),,XLOOKUP($I$5,Glossary!B:B,Glossary!D:D,1,1,1))}
A31: 3 | B31: 特性參數
C32: 保險箱層數固定為5層。
C34: 保險箱尺寸固定為2*2地塊。
C36: 保險箱每層的外型都會有變化。
C38: 編輯器可設定繩索為盤面的通關目標及所需數量。

Sheet 18.拖鞋
A1: 拖鞋 | C1: 靜態圖檔名： | D1: Ingredients_Donus | H1: 返回清單
A3: 1 | B3: 關鍵字
C4: 類型 | D4: 屬性1 | E4: 屬性2 | F4: 盤面運動 | G4: 消除類型 | H4: 消除方式1 | I4: 消除方式2 | J4: RM對應 | K4: RM初現關卡
C5: 接收型 | D5: {=XLOOKUP($A$1,'清單'!$B$4:$B$26,'清單'!D4:D26,0,1,1)} -> 複數地塊 | E5: {=XLOOKUP($A$1,'清單'!$B$4:$B$26,'清單'!E4:E26,0,1,1)} -> 特殊屬性 | F5: {=XLOOKUP($A$1,'清單'!$B$4:$B$26,'清單'!F4:F26,0,1,1)} -> 固定 | G5: {=XLOOKUP($A$1,'清單'!$B$4:$B$26,'清單'!G4:G26,0,1,1)} -> 混合消除 | H5: {=XLOOKUP($A$1,'清單'!$B$4:$B$26,'清單'!H4:H26,0,1,1)} -> 鄰邊消除 | I5: {=XLOOKUP($A$1,'清單'!$B$4:$B$26,'清單'!I4:I26,0,1,1)} -> 道具消除 | J5: {=XLOOKUP($A$1,'清單'!$B$4:$B$26,'清單'!J4:J26,0,1,1)} | K5: {=XLOOKUP($A$1,'清單'!$B$4:$B$26,'清單'!K4:K26,0,1,1)} -> 401
A8: 2 | B8: 特性規則 | M8: 2.5 | N8: 甜甜圈接收器特性規則
C9: =C4 -> 類型 | D9: 描述 | O9: 甜甜圈接受器為地形的一種。
C10: =C5 -> 接收型 | D10: {=XLOOKUP($C$5,Glossary!$B:$B,Glossary!$D:$D,1,1,1)} -> 接收型障礙物只能在落入對應的接收器時才可被消除。接收型障礙物可移動，接收器不可移動、不占空間。 | O10: 甜甜圈接受器沒有美術圖，僅有局部動態特效提示玩家將甜甜圈引導至該處。
O11: 當甜甜圈抵達該地塊(即便只有路途經過)，則甜甜圈視為被完成。
C12: 屬性1 | D12: 描述 | O12: 甜甜圈完成後，盤面甜甜圈會從盤面上消失，並且通關目標將完成的甜甜圈記數。
C13: =if(ISBLANK($D$5),"無",CONCATENATE($D$5)) -> 複數地塊 | D13: {=if(ISBLANK($D$5),"無",XLOOKUP($D$5,Glossary!B:B,Glossary!D:D,1,1,1))} -> 物件最小存在單位超過一個地塊。
O14: 下圖紅框處為小丸子專案的表現方式。
C15: 屬性2 | D15: 描述
C16: =if(ISBLANK($E$5),"無",CONCATENATE($E$5)) -> 特殊屬性 | D16: {=if(ISBLANK($E$5),"無",XLOOKUP($E$5,Glossary!B:B,Glossary!D:D,1,1,1))} -> 雖然障礙物大致上符合某種類型的劃分，但有局部獨特的效果屬性，在清單中以此做分類，並會在該障礙物文件中詳細闡述。
C18: 盤面運動 | D18: 描述
C19: =if(ISBLANK($F$5),,CONCATENATE($F$5)) -> 固定 | D19: {=if(ISBLANK($F$5),,XLOOKUP($F$5,Glossary!B:B,Glossary!D:D,1,1,1))} -> 當物件屬性為固定時，代表物件在盤面的位置不會變動，且不會被滑動、交換及掉落。盤面運動屬性為固定的物件，都無法透過生成器生成。
C21: 消除類型 | D21: 描述
C22: =if(ISBLANK($G$5),"無",CONCATENATE($G$5)) -> 混合消除 | D22: {=if(ISBLANK($G$5),"無",XLOOKUP($G$5,Glossary!B:B,Glossary!D:D,1,1,1))} -> 單一障礙物的不同層級，存在單次消除和多次消除的設定，定義為混合消除。避免設計者混淆。
C24: 消除方式1 | D24: 描述
C25: =if(ISBLANK($H$5),"無",CONCATENATE($H$5)) -> 鄰邊消除 | D25: {=if(ISBLANK($H$5),,XLOOKUP($H$5,Glossary!B:B,Glossary!D:D,1,1,1))} -> 在與物件相鄰的地塊觸發消除行為時，會對物件產生消除效果。
C27: 消除方式2 | D27: 描述
C28: =if(ISBLANK($I$5),"無",CONCATENATE($I$5)) -> 道具消除 | D28: {=if(ISBLANK($I$5),,XLOOKUP($I$5,Glossary!B:B,Glossary!D:D,1,1,1))} -> 由道具發出的消除行為，會對物件產生消除效果。
A31: 3 | B31: 特性參數 | M31: 3.5 | N31: 甜甜圈接收器特性參數
C32: 編輯器可設定生成器的甜甜圈生成機率，預設機率為0。 | O32: 無
C34: 編輯器可設定單一生成器的甜甜圈最大生成數量，預設為無限制。
C36: 編輯器可設定全局甜甜圈最大生成數量，預設為無限制。
C38: 編輯器可設定甜甜圈為盤面的通關目標及所需數量。
C40: 有甜甜圈出現的盤面，必須要設置甜甜圈回收器，確保可通關。
A43: 4 | B43: 甜甜圈的紙飛機行為模式與權重計算
C44: 甜甜圈具有兩個狀要的特性，無法被消除、要落在接收器上。
C45: 所以紙飛機對於甜甜圈物件的作用需要特別處理。
C46: A | D46: 由於甜甜圈無法被消除，所以紙飛機不可直接將甜甜圈選為撞擊目標，避免發生無效消除行為。
C48: B | D48: 由於甜甜圈必須要落在接收器中才算完成，所以紙飛機應該要以將甜甜圈引導至接收器為目的而選定撞擊目標。
C50: 有鑑於A、B特性，以下將對紙飛機在盤面上有甜甜圈時的行為做定義：
D51: 當盤面上有甜甜圈時，甜甜圈不會被紙飛機選為撞擊目標。 | H51: (甜甜圈本體權重=0)
D52: 當甜甜圈被物件覆蓋時，針對覆蓋物件追加額外權重。 | H52: (覆蓋甜甜圈的物件權重+150)
D53: 當甜甜圈下方有可消除的物件時，針對下方物件追加額外權重。 | H53: (甜甜圈下方物件權重+100)
D54: (嚴格來說是沿重力方向行進的下一個地塊，但目前尚未製作重力，故以下方替代)
D55: 上述三種狀況的權重，都可和其他權重加總計算。

Sheet 19.彩色紙箱
A1: 彩色紙箱 | C1: 靜態圖檔名： | D1: Color Box | H1: 返回清單
A3: 1 | B3: 關鍵字
C4: 類型 | D4: 屬性1 | E4: 屬性2 | F4: 盤面運動 | G4: 消除類型 | H4: 消除方式1 | I4: 消除方式2 | J4: RM對應 | K4: RM初現關卡
C5: {=XLOOKUP($A$1,'清單'!$B$4:$B$26,'清單'!C4:C26,0,1,1)} -> 一般型 | D5: {=XLOOKUP($A$1,'清單'!$B$4:$B$26,'清單'!D4:D26,0,1,1)} -> 對應顏色 | E5: {=XLOOKUP($A$1,'清單'!$B$4:$B$26,'清單'!E4:E26,0,1,1)} | F5: {=XLOOKUP($A$1,'清單'!$B$4:$B$26,'清單'!F4:F26,0,1,1)} -> 固定 | G5: {=XLOOKUP($A$1,'清單'!$B$4:$B$26,'清單'!G4:G26,0,1,1)} -> 單次消除 | H5: {=XLOOKUP($A$1,'清單'!$B$4:$B$26,'清單'!H4:H26,0,1,1)} -> 鄰邊消除 | I5: {=XLOOKUP($A$1,'清單'!$B$4:$B$26,'清單'!I4:I26,0,1,1)} -> 道具消除 | J5: {=XLOOKUP($A$1,'清單'!$B$4:$B$26,'清單'!J4:J26,0,1,1)} -> Color Box | K5: {=XLOOKUP($A$1,'清單'!$B$4:$B$26,'清單'!K4:K26,0,1,1)} -> 121
A8: 2 | B8: 特性規則
C9: =C4 -> 類型 | D9: 描述
C10: =C5 -> 一般型 | D10: {=XLOOKUP($C$5,Glossary!$B:$B,Glossary!$D:$D,1,1,1)} -> 最基礎的障礙物，具備1~N層，主要透過鄰邊消除和道具消除的手段來消除。
C12: 屬性1 | D12: 描述
C13: =if(ISBLANK($D$5),"無",CONCATENATE($D$5)) -> 對應顏色 | D13: {=if(ISBLANK($D$5),"無",XLOOKUP($D$5,Glossary!B:B,Glossary!D:D,1,1,1))} -> 需要對應顏色的元素消除才能做出有效消除。
C15: 屬性2 | D15: 描述
C16: =if(ISBLANK($E$5),"無",CONCATENATE($E$5)) -> 無 | D16: {=if(ISBLANK($E$5),"無",XLOOKUP($E$5,Glossary!B:B,Glossary!D:D,1,1,1))} -> 無
C18: 盤面運動 | D18: 描述
C19: =if(ISBLANK($F$5),,CONCATENATE($F$5)) -> 固定 | D19: {=if(ISBLANK($F$5),,XLOOKUP($F$5,Glossary!B:B,Glossary!D:D,1,1,1))} -> 當物件屬性為固定時，代表物件在盤面的位置不會變動，且不會被滑動、交換及掉落。盤面運動屬性為固定的物件，都無法透過生成器生成。
C21: 消除類型 | D21: 描述
C22: =if(ISBLANK($G$5),"無",CONCATENATE($G$5)) -> 單次消除 | D22: {=if(ISBLANK($G$5),"無",XLOOKUP($G$5,Glossary!B:B,Glossary!D:D,1,1,1))} -> 設定為單次消除的層級，在一次消除行為下，只能被消除一次。該次消除行為包含的複數地塊消除，都算是該單次消除行為。
C24: 消除方式1 | D24: 描述
C25: =if(ISBLANK($H$5),"無",CONCATENATE($H$5)) -> 鄰邊消除 | D25: {=if(ISBLANK($H$5),,XLOOKUP($H$5,Glossary!B:B,Glossary!D:D,1,1,1))} -> 在與物件相鄰的地塊觸發消除行為時，會對物件產生消除效果。
C27: 消除方式2 | D27: 描述
C28: =if(ISBLANK($I$5),"無",CONCATENATE($I$5)) -> 道具消除 | D28: {=if(ISBLANK($I$5),,XLOOKUP($I$5,Glossary!B:B,Glossary!D:D,1,1,1))} -> 由道具發出的消除行為，會對物件產生消除效果。
A31: 3 | B31: 特性參數
C32: 編輯器可設定彩色木箱層數1~4層。
C34: 彩色木箱外型的顏色對應可消除的基礎元素顏色。
C36: 彩色木箱每層的外型都會有變化。
C38: 編輯器可設定繩索為盤面的通關目標及所需數量。
A41: 4 | B41: 備註
C42: 彩色木箱現在和一般元素同高度，彼此不能覆蓋，請留意。

Sheet 20.冰塊
A1: 禁入膠帶 | C1: 靜態圖檔名： | D1: Ice_Maruko | H1: 返回清單
A3: 1 | B3: 關鍵字
C4: 類型 | D4: 屬性1 | E4: 屬性2 | F4: 盤面運動 | G4: 消除類型 | H4: 消除方式1 | I4: 消除方式2 | J4: RM對應 | K4: RM初現關卡
C5: {=XLOOKUP($A$1,'清單'!$B$4:$B$26,'清單'!C4:C26,0,1,1)} -> 特殊 | D5: {=XLOOKUP($A$1,'清單'!$B$4:$B$26,'清單'!D4:D26,0,1,1)} -> 複數地塊 | E5: {=XLOOKUP($A$1,'清單'!$B$4:$B$26,'清單'!E4:E26,0,1,1)} -> 特殊屬性 | F5: {=XLOOKUP($A$1,'清單'!$B$4:$B$26,'清單'!F4:F26,0,1,1)} -> 固定 | G5: {=XLOOKUP($A$1,'清單'!$B$4:$B$26,'清單'!G4:G26,0,1,1)} -> 多次消除 | H5: {=XLOOKUP($A$1,'清單'!$B$4:$B$26,'清單'!H4:H26,0,1,1)} -> 鄰邊消除 | I5: {=XLOOKUP($A$1,'清單'!$B$4:$B$26,'清單'!I4:I26,0,1,1)} -> 道具消除 | J5: {=XLOOKUP($A$1,'清單'!$B$4:$B$26,'清單'!J4:J26,0,1,1)} -> Ice/potion tube | K5: {=XLOOKUP($A$1,'清單'!$B$4:$B$26,'清單'!K4:K26,0,1,1)} -> 141/9401
A8: 2 | B8: 特性規則
C9: =C4 -> 類型 | D9: 描述
C10: =C5 -> 特殊 | D10: {=XLOOKUP($C$5,Glossary!$B:$B,Glossary!$D:$D,1,1,1)} -> 具有複合性的或獨特效果的障礙物，為避免設計者混淆，皆列入特殊類型以供辨識。
C12: 屬性1 | D12: 描述
C13: =if(ISBLANK($D$5),"無",CONCATENATE($D$5)) -> 複數地塊 | D13: {=if(ISBLANK($D$5),"無",XLOOKUP($D$5,Glossary!B:B,Glossary!D:D,1,1,1))} -> 物件最小存在單位超過一個地塊。
C15: 屬性2 | D15: 描述
C16: =if(ISBLANK($E$5),"無",CONCATENATE($E$5)) -> 特殊屬性 | D16: {=if(ISBLANK($E$5),"無",XLOOKUP($E$5,Glossary!B:B,Glossary!D:D,1,1,1))} -> 雖然障礙物大致上符合某種類型的劃分，但有局部獨特的效果屬性，在清單中以此做分類，並會在該障礙物文件中詳細闡述。
C18: 盤面運動 | D18: 描述
C19: =if(ISBLANK($F$5),,CONCATENATE($F$5)) -> 固定 | D19: {=if(ISBLANK($F$5),,XLOOKUP($F$5,Glossary!B:B,Glossary!D:D,1,1,1))} -> 當物件屬性為固定時，代表物件在盤面的位置不會變動，且不會被滑動、交換及掉落。盤面運動屬性為固定的物件，都無法透過生成器生成。
C21: 消除類型 | D21: 描述
C22: =if(ISBLANK($G$5),"無",CONCATENATE($G$5)) -> 多次消除 | D22: {=if(ISBLANK($G$5),"無",XLOOKUP($G$5,Glossary!B:B,Glossary!D:D,1,1,1))} -> 障礙物連續受到多次消除，會造成對應消除次數的效果，沒有其他條件。特別是複數地塊物件，每個地塊受到的消除都會計算。
C24: 消除方式1 | D24: 描述
C25: =if(ISBLANK($H$5),"無",CONCATENATE($H$5)) -> 鄰邊消除 | D25: {=if(ISBLANK($H$5),,XLOOKUP($H$5,Glossary!B:B,Glossary!D:D,1,1,1))} -> 在與物件相鄰的地塊觸發消除行為時，會對物件產生消除效果。
C27: 消除方式2 | D27: 描述
C28: =if(ISBLANK($I$5),"無",CONCATENATE($I$5)) -> 道具消除 | D28: {=if(ISBLANK($I$5),,XLOOKUP($I$5,Glossary!B:B,Glossary!D:D,1,1,1))} -> 由道具發出的消除行為，會對物件產生消除效果。
A31: 3 | B31: 特性參數
C32: 編輯器可設定冰塊尺寸為1*(2~9)。 | E32: (第1層是基底，第2層開始才是冰塊)
C34: 每受到1次消除，冰塊退縮一格。 | E34: https://static.wikia.nocookie.net/royalmatch/images/e/e0/Ice_Tutorial_Final.gif/revision/latest?cb=20230326164938
C36: 編輯器可設定冰塊的方向。 | E36: (可設定上、下、左、右，差異為冰塊受到消除後往什麼方位退縮)
C38: 編輯器可設定冰塊為盤面的通關目標及所需數量。

Sheet 21.玻璃罐頭
A1: 玻璃罐頭 | C1: 靜態圖檔名： | D1: 小丸子專案內無類似靜態圖 | H1: 返回清單
A3: 1 | B3: 關鍵字
C4: 類型 | D4: 屬性1 | E4: 屬性2 | F4: 盤面運動 | G4: 消除類型 | H4: 消除方式1 | I4: 消除方式2 | J4: RM對應 | K4: RM初現關卡
C5: {=XLOOKUP($A$1,'清單'!$B$4:$B$26,'清單'!C4:C26,0,1,1)} -> 一般型 | D5: {=XLOOKUP($A$1,'清單'!$B$4:$B$26,'清單'!D4:D26,0,1,1)} | E5: {=XLOOKUP($A$1,'清單'!$B$4:$B$26,'清單'!E4:E26,0,1,1)} -> 特殊屬性 | F5: {=XLOOKUP($A$1,'清單'!$B$4:$B$26,'清單'!F4:F26,0,1,1)} -> 固定 | G5: {=XLOOKUP($A$1,'清單'!$B$4:$B$26,'清單'!G4:G26,0,1,1)} -> 單次消除 | H5: {=XLOOKUP($A$1,'清單'!$B$4:$B$26,'清單'!H4:H26,0,1,1)} -> 鄰邊消除 | I5: {=XLOOKUP($A$1,'清單'!$B$4:$B$26,'清單'!I4:I26,0,1,1)} -> 道具消除 | J5: {=XLOOKUP($A$1,'清單'!$B$4:$B$26,'清單'!J4:J26,0,1,1)} | K5: {=XLOOKUP($A$1,'清單'!$B$4:$B$26,'清單'!K4:K26,0,1,1)} -> 301
A8: 2 | B8: 特性規則
C9: =C4 -> 類型 | D9: 描述
C10: =C5 -> 一般型 | D10: {=XLOOKUP($C$5,Glossary!$B:$B,Glossary!$D:$D,1,1,1)} -> 最基礎的障礙物，具備1~N層，主要透過鄰邊消除和道具消除的手段來消除。
C12: 屬性1 | D12: 描述
C13: =if(ISBLANK($D$5),"無",CONCATENATE($D$5)) -> 無 | D13: {=if(ISBLANK($D$5),"無",XLOOKUP($D$5,Glossary!B:B,Glossary!D:D,1,1,1))} -> 無
C15: 屬性2 | D15: 描述
C16: =if(ISBLANK($E$5),"無",CONCATENATE($E$5)) -> 特殊屬性 | D16: {=if(ISBLANK($E$5),"無",XLOOKUP($E$5,Glossary!B:B,Glossary!D:D,1,1,1))} -> 雖然障礙物大致上符合某種類型的劃分，但有局部獨特的效果屬性，在清單中以此做分類，並會在該障礙物文件中詳細闡述。
C18: 盤面運動 | D18: 描述
C19: =if(ISBLANK($F$5),,CONCATENATE($F$5)) -> 固定 | D19: {=if(ISBLANK($F$5),,XLOOKUP($F$5,Glossary!B:B,Glossary!D:D,1,1,1))} -> 當物件屬性為固定時，代表物件在盤面的位置不會變動，且不會被滑動、交換及掉落。盤面運動屬性為固定的物件，都無法透過生成器生成。
C21: 消除類型 | D21: 描述
C22: =if(ISBLANK($G$5),"無",CONCATENATE($G$5)) -> 單次消除 | D22: {=if(ISBLANK($G$5),"無",XLOOKUP($G$5,Glossary!B:B,Glossary!D:D,1,1,1))} -> 設定為單次消除的層級，在一次消除行為下，只能被消除一次。該次消除行為包含的複數地塊消除，都算是該單次消除行為。
C24: 消除方式1 | D24: 描述
